Workbook
Name _\a: #REF!
Name __\a: #REF!
Name _\AUTOEXEC: #REF!
Name __\AUTOEXEC: #REF!
Name ___\AUTOEXEC: #REF!
Name ____\AUTOEXEC: #REF!
Name _\HOMEPOS: #REF!
Name __\HOMEPOS: #REF!
Name _\k: #REF!
Name __\k: #REF!
Name ___\k: #REF!
Name ____\k: #REF!
Name _\m: #REF!
Name __\m: #REF!
Name ___\m: #REF!
Name ____\m: #REF!
Name _\n: #REF!
Name __\n: #REF!
Name _\o: #REF!
Name __\o: #REF!
Name _\s: #REF!
Name __\s: #REF!
Name ___\s: #REF!
Name ____\s: #REF!
Name _\z: #REF!
Name __\z: #REF!
Name ___\z: #REF!
Name ____\z: #REF!
Name ___________________a2: #REF!
Name ___________________a2: #REF!
Name __________________a2: #REF!
Name __________________a2: #REF!
Name _________________a2: #REF!
Name _________________a2: #REF!
Name ________________a2: #REF!
Name ________________a2: #REF!
Name ________________k116: '[1]Зап-3- СЦБ'!#REF!
Name ________________k116: '[1]Зап-3- СЦБ'!#REF!
Name ________________k116: '[1]Зап-3- СЦБ'!#REF!
Name ________________k116: '[1]Зап-3- СЦБ'!#REF!
Name ________________k121: '[1]Зап-3- СЦБ'!#REF!
Name ________________k121: '[1]Зап-3- СЦБ'!#REF!
Name ________________k121: '[1]Зап-3- СЦБ'!#REF!
Name ________________k121: '[1]Зап-3- СЦБ'!#REF!
Name _______________a2: #REF!
Name _______________a2: #REF!
Name ______________a2: #REF!
Name ______________a2: #REF!
Name ______________k116: '[1]Зап-3- СЦБ'!#REF!
Name ______________k116: '[1]Зап-3- СЦБ'!#REF!
Name ______________k116: '[1]Зап-3- СЦБ'!#REF!
Name ______________k116: '[1]Зап-3- СЦБ'!#REF!
Name ______________k121: '[1]Зап-3- СЦБ'!#REF!
Name ______________k121: '[1]Зап-3- СЦБ'!#REF!
Name ______________k121: '[1]Зап-3- СЦБ'!#REF!
Name ______________k121: '[1]Зап-3- СЦБ'!#REF!
Name _____________a2: #REF!
Name _____________a2: #REF!
Name _____________k116: '[1]Зап-3- СЦБ'!#REF!
Name _____________k116: '[1]Зап-3- СЦБ'!#REF!

Sheet Обложка ДКС

Sheet Тит. лист ДКС

Sheet Тит. лист СГТ

Sheet Содержание
A2: СОДЕРЖАНИЕ
A4: №пп | B4: Обозначение | C4: Наименование | D4: стр.
A5: 1 | B5: 2 | C5: 3 | D5: =C5+1 -> 4
C6: Том 9.2.10
A7: 1 | B7: Сводная смета БЦ | C7: Сводная смета на проектные работы и инженерные изыскания (базисный уровень цен)
A8: =A7+1 -> 2 | B8: Сводная смета ТЦ | C8: Сводная смета на проектные работы и инженерные изыскания (текущий уровень цен)
A9: =A8+1 -> 3 | B9: Исполнительная смета №1.1 | C9: Исполнительная смета на проектные (изыскательские) работы
A10: =A9+1 -> 4 | B10: Смета №1.2 | C10: Смета на инженерно-геодезические изыскания (восстановление и закрепление оси Ж.Д.)
A11: =A10+1 -> 5 | B11: Смета №1.3 | C11: Смета на инженерно-геодезические изыскания (восстановление и закрепление оси трассы А.Д.)
A12: =A11+1 -> 6 | B12: Исполнительная смета №2 | C12: Исполнительная смета на инженерно-гидрометеорологические изыскания
A13: =A12+1 -> 7 | B13: Смета №3 | C13: Инженерно-экологические изыскания
A14: =A13+1 -> 8 | B14: Исполнительная смета №4 | C14: Исполнительная смета на полевые инженерно-геологические работы
A15: =A14+1 -> 9 | B15: Смета №5 | C15: Геофизические работы
A16: =A15+1 -> 10 | B16: Смета №6 | C16: Смета на проектные (изыскательские) работы (пути железнодорожные)
A17: =A16+1 -> 11 | B17: Смета №7 | C17: Смета на проектные (изыскательские) работы (искусственные сооружения)
A18: =A17+1 -> 12 | B18: Смета №8 | C18: Смета на проектные и изыскательские работы (здания и сооружения)
A19: =A18+1 -> 13 | B19: Смета №9 | C19: Смета на проектные и изыскательские работы (водоснабжение и водоотведение)
... A26: =A25+1 -> 20 | B26: Смета №16 | C26: Обследование на участке автомобильной дороги «Подъезд к д. Шоша»

Sheet БЦ
F1: Форма 1пс
A4: СВОДНАЯ СМЕТА
A5: на проектные работы и инженерные изыскания
C6: Организация пассажирского сообщения от станции Москва - Октябрьская - Пассажирская до проектируемого транспортно-пересадочного узла «Завидово» через остановочный пункт Путепроводная Октябрьской железной дороги Этап 2. Строительство железнодорожной линии от примыкания к Октябрьской железной дороге до проектируемого ТПУ «Завидово»
B7: Наименование предприятия,
B8: здания, сооружения
B10: Заказчик | C10: ГКУ "Дирекция ТДФ"
B11: Генеральный проектировщик | C11: ООО "ДСК"
B12: Проектная организация | C12: ОАО "Сибгипротранс"
A14: Составлена в уровне цен на ________________ 20__ г.
A15: № п/п | B15: Наименование смет на проектные работы и инженерные изыскания, затрат | C15: Ссылка на №№смет по формам 2п и 3п | D15: Сметная стоимость, тыс. руб.
D16: инженерных изысканий | E16: проектных работ
A17: 1 | B17: Изыскательские работы
A18: 1 | B18: Инженерно-геодезические изыскания. | C18: 1.1 (ф.2п) | D18: ='№1.1 ИГДИ'!K57 -> 34.28575
A19: 2 | B19: Инженерно-геодезические изыскания. | C19: 1.2 (ф.2п) | D19: ='№1.2 ИГДИ Разбивка ж.д.'!K62 -> 123.30821
A20: 3 | B20: Инженерно-геодезические изыскания. | C20: 1.3 (ф.2п) | D20: ='№1.3 ИГДИ Разбивка а.д.'!K64 -> 7.7589755
A21: 4 | B21: Инженерно-гидрометеорологические изыскания | C21: 2 (ф.2п) | D21: ='№2 ИГМИ'!L263 -> 331.70383
A22: 5 | B22: Инженерно-экологические изыскания. | C22: 3 (ф.2п) | D22: ='№3 ИЭИ'!I45 -> 105.74729
A23: 6 | B23: Инженерно-геологические изыскания. | C23: 4 (ф.2п) | D23: ='№4 ИГИ'!O119 -> 2377.68
A24: 7 | B24: Инженерно-геофизические изыскания. | C24: 5 (ф.2п) | D24: ='№5 ИГФИ'!O64 -> 393.2853
A25: 8 | B25: Обследование на участке автомобильной дороги | C25: 16 (ф.3П) | D25: ='№16 Обследования ОР2'!D20 -> 11.976329
B26: Всего по изыскательским работам | D26: =SUM(D18:D24) -> 3373.7694
B27: Проектная документация
A28: 9 | B28: Пути железнодорожные | C28: 6 (ф.2п) | E28: ='№6 ПД ПЖ'!E37 -> 1205.1736
A29: 10 | B29: Искусственные сооружения | C29: 7 (ф.2п) | E29: ='№7 ПД ИССО'!E55 -> 239.1524
A30: 11 | B30: Здания и сооружения | C30: 8 (ф.2п) | E30: ='№8 ПД Здания'!E51 -> 1966.14
A31: 12 | B31: Водоснабжение и водоотведение | C31: 9 (ф.2п) | E31: ='№9 ПД Водоснабжение'!E31 -> 632.3188
A32: 13 | B32: Электроснабжение и электросовещение | C32: 10 (ф.2п) | E32: ='№10 ПД ЭС'!E725 -> 1549.4105
A33: 14 | B33: Электроснабжение (Тяговая подстанция, Пункт питания) | C33: 11 (ф.2п) | E33: ='№11 УГТ ПД ЭС Тяговые'!I112 -> 497.5484
A34: 15 | B34: Контактная сеть | C34: 12 (ф.2п) | E34: ='№12 УГТ ПД КС'!F52 -> 625.51276
A35: 16 | B35: Устройства СЦБ | C35: 13 (ф.2п) | E35: ='№13 УГТ ПД СЦБ'!I88 -> 2188.948
A36: 17 | B36: Подъездные автомобильные дороги | C36: 14 (ф.2п) | E36: ='№14 ПД АД Подъездные'!G22 -> 80.6084
A37: 18 | B37: Автомобильная дорога Ж.д. переезд | C37: 15 (ф.2п) | E37: ='№15 ПД АД Ж,Д, переезд'!G23 -> 147.168
B38: Всего проектных работ | E38: =SUM(E28:F37) -> 9131.9809
B40: Рабочая документация
A41: 19 | B41: Пути железнодорожные | C41: 6 (ф.2п) | E41: ='№6 ПД ПЖ'!E38 -> 1807.7604
A42: 20 | B42: Искусственные сооружения | C42: 7 (ф.2п) | E42: ='№7 ПД ИССО'!E56 -> 358.7286
A43: 21 | B43: Здания и сооружения | C43: 8 (ф.2п) | E43: ='№8 ПД Здания'!E52 -> 2949.21
A44: 22 | B44: Водоснабжение и водоотведение | C44: 9 (ф.2п) | E44: ='№9 ПД Водоснабжение'!E32 -> 948.4782
A45: 23 | B45: Электроснабжение и электросовещение | C45: 10 (ф.2п) | E45: ='№10 ПД ЭС'!E726 -> 2324.1157
...

Sheet 1кв 2024
F1: Форма 1пс
A3: СВОДНАЯ СМЕТА
A4: на проектные работы и инженерные изыскания
C5: Организация пассажирского сообщения от станции Москва - Октябрьская - Пассажирская до проектируемого транспортно-пересадочного узла «Завидово» через остановочный пункт Путепроводная Октябрьской железной дороги Этап 2. Строительство железнодорожной линии от примыкания к Октябрьской железной дороге до проектируемого ТПУ «Завидово»
B6: Наименование предприятия,
B7: здания, сооружения
B9: Заказчик | C9: ГКУ "Дирекция ТДФ"
B10: Генеральный проектировщик | C10: ООО "ДСК"
B11: Проектная организация | C11: ОАО "Сибгипротранс"
A13: Составлена в уровне цен на 1 квартал 2024 г.
A14: № п/п | B14: Наименование смет на проектные работы и инженерные изыскания, затрат | C14: Ссылка на №№смет по формам 2п и 3п | D14: Сметная стоимость, тыс. руб.
D15: инженерных изысканий | E15: проектных работ
A16: 1 | B16: Изыскательские работы
A17: 1 | B17: Инженерно-геодезические изыскания. | C17: 1.1 (ф.2п) | D17: ='№1.1 ИГДИ'!K60 -> 199.88592
A18: 2 | B18: Инженерно-геодезические изыскания. | C18: 1.2 (ф.2п) | D18: ='№1.2 ИГДИ Разбивка ж.д.'!K65 -> 718.88688
A19: 3 | B19: Инженерно-геодезические изыскания. | C19: 1.3 (ф.2п) | D19: ='№1.3 ИГДИ Разбивка а.д.'!K67 -> 45.234827
A20: 4 | B20: Инженерно-гидрометеорологические изыскания | C20: 2 (ф.2п) | D20: ='№2 ИГМИ'!L261 -> 1933.8333
A21: 5 | B21: Инженерно-экологические изыскания. | C21: 3 (ф.2п) | D21: ='№3 ИЭИ'!I44 -> 616.50671
A22: 6 | B22: Инженерно-геологические изыскания. | C22: 4 (ф.2п) | D22: ='№4 ИГИ'!O117 -> 13861.875
A23: 7 | B23: Инженерно-геофизические изыскания. | C23: 5 (ф.2п) | D23: ='№5 ИГФИ'!O63 -> 2292.8533
A24: 8 | B24: Обследование на участке автомобильной дороги | C24: 16 (ф.3П) | D24: ='№16 Обследования ОР2'!D19 -> 69.822
B25: Всего по изыскательским работам | D25: =SUM(D17:D23) -> 19669.075
B26: Проектная документация
A27: 9 | B27: Пути железнодорожные | C27: 6 (ф.2п) | E27: ='№6 ПД ПЖ'!E41 -> 7002.0586
A28: 10 | B28: Искусственные сооружения | C28: 7 (ф.2п) | E28: ='№7 ПД ИССО'!E59 -> 1389.4754
A29: 11 | B29: Здания и сооружения | C29: 8 (ф.2п) | E29: ='№8 ПД Здания'!E55 -> 11423.273
A30: 12 | B30: Водоснабжение и водоотведение | C30: 9 (ф.2п) | E30: ='№9 ПД Водоснабжение'!E35 -> 3673.7722
A31: 13 | B31: Электроснабжение и электросовещение | C31: 10 (ф.2п) | E31: ='№10 ПД ЭС'!E729 -> 9002.075
A32: 14 | B32: Электроснабжение (Тяговая подстанция, Пункт питания) | C32: 11 (ф.2п) | E32: ='№11 УГТ ПД ЭС Тяговые'!I116 -> 2890.7562
A33: 15 | B33: Контактная сеть | C33: 12 (ф.2п) | E33: ='№12 УГТ ПД КС'!F56 -> 3634.2291
A34: 16 | B34: Устройства СЦБ | C34: 13 (ф.2п) | E34: ='№13 УГТ ПД СЦБ'!I92 -> 12717.788
A35: 17 | B35: Подъездные автомобильные дороги | C35: 14 (ф.2п) | E35: ='№14 ПД АД Подъездные'!G25 -> 468.336
A36: 18 | B36: Автомобильная дорога Ж.д. переезд | C36: 15 (ф.2п) | E36: ='№15 ПД АД Ж,Д, переезд'!G26 -> 855.048
B37: Всего проектных работ | E37: =SUM(E27:F36) -> 53056.812
B39: Рабочая документация
A40: 19 | B40: Пути железнодорожные | C40: 6 (ф.2п) | E40: ='№6 ПД ПЖ'!E42 -> 10503.088
A41: 20 | B41: Искусственные сооружения | C41: 7 (ф.2п) | E41: ='№7 ПД ИССО'!E60 -> 2084.2132
A42: 21 | B42: Здания и сооружения | C42: 8 (ф.2п) | E42: ='№8 ПД Здания'!E56 -> 17134.91
A43: 22 | B43: Водоснабжение и водоотведение | C43: 9 (ф.2п) | E43: ='№9 ПД Водоснабжение'!E36 -> 5510.6583
A44: 23 | B44: Электроснабжение и электросовещение | C44: 10 (ф.2п) | E44: ='№10 ПД ЭС'!E730 -> 13503.112
...

Sheet №1.1 ИГДИ
H1: Форма №2п
B2: Приложение к договору №
B3: (договору, дополнительному соглашению, наряд-заказу)
B5: Исполнительная смета № 1.1
B6: на проектные (изыскательские) работы
B7: Стадия проектирования | C7: Проектная документация
B8: Наименование строительства | C8: Организация пассажирского сообщения от станции Москва-Октябрьская-Пассажирская до проектируемого ТПУ "Завидово" через остановочный пункт Путепроводная Октябрьской железной дороги. Этап 2. Строительство железнодорожной линии от примыкания к Октябрьской железной дороге до проектируемого ТПУ «Завидово»
B9: Наменование проектной
B10: (изыскательской) организации | C10: ОАО "Сибгипротранс"
B11: Наименоваеие организации- | C11: ООО "ДСК"
B12: заказчика
C14: №№ частей, глав, | D14: Расчет стоимости
C15: таблиц, $$ и пунк- | D15: а+вх
A16: № | B16: Характеристика предприятия, здания, | C16: тов указаний к раз- | D16: или объем строитель- | K16: Стоимость
A17: пп | B17: сооружения или виды работ | C17: делу или главе | D17: но монтажных работ | K17: (руб.)
C18: Сборника цен на | D18: х%:100
C19: проектные и изыс- | D19: или количество х цена
C20: кательские работы
A21: 1 | B21: 2 | C21: 3 | D21: 4 | K21: 5
B22: Инженерно-геодезические работы СБЦ-2004г.
A25: 1 | B25: Создание инженерно-топографичес- | C25: Тб.9, §11 | D25: Полевые работы
B26: ких планов М 1:1000, сечение гори-
B27: зонталей 0,5м | D27: 2258 | E27: * | F27: 4.6 | G27: * | H27: 1.55 | K27: =D27*F27*H27 -> 16099.54
B28: Категория сложности II,
B29: застроенная территория
B30: Объём работ: 4,6 га | D30: Камеральные работы
B31: К- 1,2 применение комп.технологий | C31: Об.указания п.15д | D31: 734 | E31: * | F31: 4.6 | G31: * | H31: 1.2 | I31: * | J31: 1.15 | K31: =D31*F31*H31*J31 -> 4659.432
B32: К-1,55 за съемку подзем. коммуникац. | C32: Тб.9, прим. 4
B33: с помощью трубокабелеискателя и
B34: составление плана подземных коммун.
B35: на застр.территории.
B36: К-1,15 за камер.обработ. в поле | C36: Об.указания п.14
B39: Итого | K39: =SUM(K23:K37) -> 20758.972
B40: в т.ч. Полевые работы | K40: =K27 -> 16099.54
B41: Камеральные работы | K41: =K31 -> 4659.432
B42: Прочие расходы
A44: 2 | B44: Расходы по внутреннему транспорту | C44: Тб.4 §3 | D44: =K39 -> 20758.972 | E44: * | F44: 0.1375 | K44: =ROUND(D44*F44,0) -> 2854
B45: при расст. до 15 км, при сметн.
B46: стоимости пол. работ до 75т.р.
B47: 0.1375
...

Sheet №1.2 ИГДИ Разбивка ж.д.
H1: Форма №2п
B2: Приложение к доп соглашению №
B3: (договору, дополнительному соглашению, наряд-заказу)
B5: СМЕТА №1.2
B6: на инженерно-геодезические изыскания
B7: Стадия проектирования
B8: Наименование строительства | C8: Организация пассажирского сообщения от станции Москва-Октябрьская-Пассажирская до проектируемого ТПУ "Завидово" через остановочный пункт Путепроводная Октябрьской железной дороги. Этап 2. Строительство железнодорожной линии от примыкания к Октябрьской железной дороге до проектируемого ТПУ «Завидово» Восстановление и закрепление оси Ж.Д.
B14: Наменование проектной
B15: (изыскательской) организации | C15: ОАО "Сибгипротранс"
B16: Наименоваеие организации-
B17: заказчика | C17: Заказчик: ООО "ДСК"
C20: №№ частей, глав, | D20: Расчет стоимости
C21: таблиц, $$ и пунк- | D21: а+вх
A22: № | B22: Характеристика предприятия, здания, | C22: тов указаний к раз- | D22: или объем строитель- | K22: Стоимость
A23: пп | B23: сооружения или виды работ | C23: делу или главе | D23: но монтажных работ | K23: (руб.)
C24: Сборника цен на | D24: х%:100
C25: проектные и изыс- | D25: или количество х цена
C26: кательские работы
A27: 1 | B27: 2 | C27: 3 | D27: 4 | K27: 5
B28: Инженерно-геодезические работы изыскания для строительства СБЦ-2006г.
B30: Восстановление трассы | C30: Тб.16, §1 | D30: 3189 | E30: * | F30: 11.86 | K30: =D30*F30 -> 37821.54
B31: железной дороги.
A32: 1 | B32: .Категория сложности II
B33: Объём работ -11,86 км
B35: Закрепление трасс проектируемых | C35: Тб.16, §4 | D35: 1838 | E35: * | F35: 11.86 | K35: =D35*F35 -> 21798.68
B36: железных дорог. Категория
B37: сложности.Категория сложности II
A38: 2 | B38: Объём работ -11,86 км
B41: Изготовление и установка центров. | C41: Тб.10, §5 | D41: 213 | E41: * | F41: 195 | K41: =D41*F41 -> 41535
B42: Пункт разбивочной сети: деревянный
A43: 3 | B43: столб, пень (оформленный под столб),
B44: трубка на бетоне (на глубину до 0,7 м).
B45: Категория грунтов II
B46: Объём работ -195 знаков
B48: Итого по п.п. 1-3 | K48: =K30+K35+K41 -> 101155.22
B49: Прочие расходы
B51: Расходы по внешнему транспорту | D51: =K48 -> 101155.22 | E51: * | F51: 0.392 | K51: =D51*F51 -> 39652.846
A52: 4 | B52: при расстоянии св. 2000 км | C52: Тб.5 §6
B53: и продолжительности работ до 2 мес.
B54: 0.392
...

Sheet №1.3 ИГДИ Разбивка а.д.
H1: Форма №2п
B2: Приложение к доп соглашению №
B3: (договору, дополнительному соглашению, наряд-заказу)
B5: СМЕТА №1.3
B6: на инженерно-геодезические изыскания
B7: Стадия проектирования
B8: Наименование строительства | C8: Организация пассажирского сообщения от станции Москва-Октябрьская-Пассажирская до проектируемого ТПУ "Завидово" через остановочный пункт Путепроводная Октябрьской железной дороги. Этап 2. Строительство железнодорожной линии от примыкания к Октябрьской железной дороге до проектируемого ТПУ «Завидово» Восстановление и закрепление оси трассы А.Д.
B14: Наменование проектной
B15: (изыскательской) организации | C15: ОАО "Сибгипротранс"
B16: Наименоваеие организации-
B17: заказчика | C17: Заказчик: ООО "ДСК"
C20: №№ частей, глав, | D20: Расчет стоимости
C21: таблиц, $$ и пунк- | D21: а+вх
A22: № | B22: Характеристика предприятия, здания, | C22: тов указаний к раз- | D22: или объем строитель- | K22: Стоимость
A23: пп | B23: сооружения или виды работ | C23: делу или главе | D23: но монтажных работ | K23: (руб.)
C24: Сборника цен на | D24: х%:100
C25: проектные и изыс- | D25: или количество х цена
C26: кательские работы
A27: 1 | B27: 2 | C27: 3 | D27: 4 | K27: 5
B28: Инженерно-геодезические работы изыскания для строительства СБЦ-2006г.
B30: Восстановление трасс | C30: Тб.16, §1 | D30: 3189 | E30: * | F30: 0.08 | G30: * | H30: 1.2 | K30: =D30*F30*H30 -> 306.144
B31: автомобильных дорог. Категория
A32: 1 | B32: сложности.Категория сложности II
B33: Объём работ -0,08 км
B34: К- 1,2 при длинне трасс до 5км | C34: Тб.16, прим.1
B37: Закрепление трасс проектируемых | C37: Тб.16, §4 | D37: 1838 | E37: * | F37: 0.08 | G37: * | H37: 1.2 | K37: =D37*F37*H37 -> 176.448
B38: автомобильных дорог. Категория
B39: сложности.Категория сложности II
A40: 2 | B40: Объём работ -0,08 км
B41: К- 1,2 при длинне трасс до 5км | C41: Тб.16, прим.1
B43: Изготовление и установка центров. | C43: Тб.10, §5 | D43: 323 | E43: * | F43: 18 | K43: =D43*F43 -> 5814
B44: Пункт разбивочной сети: деревянный
A45: 3 | B45: столб, пень (оформленный под столб),
B46: трубка на бетоне (на глубину до 0,7 м).
B47: Категория грунтов II
B48: Объём работ -18 знаков
B50: Итого по п.п. 1-3 | K50: =K30+K37+K43 -> 6296.592
B51: Прочие расходы
B53: Расходы по внешнему транспорту | D53: =K50 -> 6296.592 | E53: * | F53: 0.392 | K53: =D53*F53 -> 2468.2641
A54: 4 | B54: при расстоянии св. 2000 км | C54: Тб.5 §6
...

Sheet №2 ИГМИ
L1: Форма 2п
A2: Приложение к договору
D4: ИСПОЛНИТЕЛЬНАЯ СМЕТА № 2
A5: на инженерно-гидрометеорологические изыскания
A7: Стадия проектирования | E7: Проектная и рабочая документация
A8: Наименование строительства | E8: Организация пассажирского сообщения от станции Москва - Октябрьская - Пассажирская до проектируемого транспортно-пересадочного узла «Завидово» через остановочный пункт Путепроводная Октябрьской железной дороги Этап 2. Строительство железнодорожной линии от примыкания к Октябрьской железной дороге до проектируемого ТПУ «Завидово»
A10: Наименование проектно
A11: (изыскательской) организации | E11: ОАО "СИБГИПРОТРАНС"
A13: Наименование организации-
A14: заказчика
A16: №№ | B16: Характеристика предприятия, | E16: №№ частей, глав, | G16: Расчет стоимости | L16: Стоимость
A17: пп | B17: здания, сооружения или виды | E17: таблиц, и пунктов | G17: а+ вх | L17: (рублей)
C18: работ | E18: указаний к разделу | G18: или объем строи-
E19: или главе Сборника | G19: тельно монтажных
E20: цен на проектные | G20: работ х% : 100
E21: и изыскательские | G21: или количество
E22: работы для | G22: х цена
E23: строительства
A24: 1 | C24: 2 | E24: 3 | G24: 4 | L24: 5
A25: Справочник базовых цен на инженерные изыскания для строительства , СБЦ - 2001. Инженерно-гидрографические работы.Инженерно-гидрометеорологические изыскания на реках.(цены приведены к базисному уровню на 01.01.91)
A26: 1.Полевые гидрологические и гидрографические работы
A27: 1 | B27: Рекогносцировочное | E27: СБЦ-01 | G27: Полевые работы
B28: обследование рек | E28: табл.43 | G28: 1 | H28: * | I28: 30 | L28: =G28*I28 -> 30
B29: Категория сложности - II | E29: пар.1 | G29: Камеральные работы
B30: Объем работ -1.0 км | G30: 1 | H30: * | I30: 10 | L30: =G30*I30 -> 10
A32: 2 | B32: Рекогносцировочное | E32: СБЦ-01 | G32: Полевые работы
B33: обследование бассейнов (станция) | E33: табл.43 | G33: 1.3 | H33: * | I33: 20 | L33: =G33*I33 -> 26
B34: Категория сложности - II | E34: пар.2 | G34: Камеральные работы
B35: Объем работ - 1.3 км | G35: 1.3 | H35: * | I35: 7 | L35: =G35*I35 -> 9.1
A37: 3 | B37: Разбивка и нивелирование | E37: СБЦ-01 | G37: Полевые работы
B38: морфометрического створа | E38: табл.24, пар. 1 | G38: 0.2 | H38: * | I38: 161 | L38: =G38*I38 -> 32.2
B39: Категория сложности - II | G39: Камеральные работы
B40: Объем работ - 0.2 км | G40: 0.2 | H40: * | I40: 14 | L40: =G40*I40 -> 2.8
B42: в т.ч. Р.Дойбица
A44: 4 | B44: Определение мгновенного уклона
B45: поверхности воды в реке при
B46: количестве урезных кольев
B47: на 1 км длины реки, 3 шт. | E47: т.26, пар.3 | G47: Полевые работы
B48: Объём - 1 определение | E48: п.14 общ.указ. | G48: 1 | H48: * | I48: 174 | L48: =G48*I48 -> 174
B49: Категория сложности - II
...

Sheet №3 ИЭИ
A1: Смета № 4
A2: на инженерно-экологические изыскания
A3: Наименование объекта изысканий | C3: «Организация пассажирского сообщения от станции Москва – Октябрьская – Пассажирская до проектируемого ТПУ «Завидово» через остановочный пункт Путепроводная Октябрьской железной дороги Этап 2. Строительство железнодорожной линии от примыкания к Октябрьской железной дороге до проектируемого ТПУ «Завидово»
A4: Заказчик: | C4: Государственное казенное учреждение Тверской области «Дирекция территориального дорожного фонда Тверской области
A5: Исполнитель: | C5: ОАО «Сибгипротранс»
A6: Сметный расчет составлен по следующим документам:
A7: СБЦ-99. Инженерно-геологические и инженерно-экологические изыскания для строительства
A8: № пп | B8: Виды работ | C8: Таблица, параграф | D8: Единицы измерения | E8: Цена единицы работ, руб. | F8: Коэффициенты | H8: Объем работ | I8: Стоимость, руб.
A9: ПОДГОТОВИТЕЛЬНЫЕ РАБОТЫ
B10: Составление и согласование программы исследований | C10: т.81 п.1 | D10: прогр. | E10: 200 | G10: 1.25 | H10: 1 | I10: =H10*E10*G10 -> 250
B11: Районный коэффициент к сметной стоимости | C11: т.3 п.3 | G11: 1.1
B12: Итого по подготовительным работам: | I12: =(I10)*G11 -> 275
A13: ПОЛЕВЫЕ РАБОТЫ
B14: Маршрутное обследование для составления инженерно-экологических карт м-ба 1:25000 при удовлетворительной проходимости | C14: т.10 п.2 | D14: км | E14: 16.6 | F14: 1.3 | H14: 18.5 | I14: =H14*E14*F14 -> 399.23
B15: Описание точек наблюдений при составлении инженерно-экологических карт (МЭД) | C15: т.11 п.2 | D15: 1 точка | E15: 11.7 | G15: 0.3 | H15: 370 | I15: =H15*E15*G15 -> 1298.7
B16: Отбор объединённых проб почво-грунтов для анализа на загрязнённость по химическим показателям (методами конверта) | C16: т.60 п.7 | D16: 1 проба | E16: 6.9 | F16: 0.9 | H16: 30 | I16: =H16*F16*E16 -> 186.3
B17: Отбор объединённых проб почво-грунтов для анализа на ЕРН | C17: т.60 п.7 | D17: 1 проба | E17: 6.9 | F17: 1.2 | H17: 12 | I17: =H17*F17*E17 -> 99.36
B18: Итого полевых работ: | I18: =SUM(I14:I17) -> 1983.59
A19: ЛАБОРАТОРНЫЕ РАБОТЫ
A20: Почвы (6)
B21: Водородный показатель рН водной вытяжки | C21: табл. 70, § 14 | D21: проба | E21: 2 | H21: 6 | I21: =H21*E21 -> 12
B22: Ртуть | C22: табл. 70, § 57 | D22: проба | E22: 7.8 | H22: 6 | I22: =PRODUCT(E22,H22) -> 46.8
B23: Мышьяк | C23: табл. 70, § 57 | D23: проба | E23: 7.8 | H23: 6 | I23: =H23*E23 -> 46.8
B24: Медь, цинк | C24: табл. 70, § 57 | D24: проба | E24: =7.8*2 -> 15.6 | H24: 6 | I24: =PRODUCT(E24,H24) -> 93.6
B25: Свинец | C25: табл. 70, § 57 | D25: проба | E25: 7.8 | H25: 6 | I25: =H25*E25 -> 46.8
B26: Кадмий | C26: табл. 70, § 57 | D26: проба | E26: 7.8 | H26: 6 | I26: =PRODUCT(E26,H26) -> 46.8
B27: Никель | C27: табл. 70, § 57 | D27: проба | E27: 7.8 | H27: 6 | I27: =H27*E27 -> 46.8
B28: Нефтяные углеводороды | C28: табл. 70, § 63 | D28: проба | E28: 19.7 | H28: 6 | I28: =PRODUCT(E28,H28) -> 118.2
B29: Бенз(а)пирен | C29: табл. 70, § 66 | D29: проба | E29: 95.8 | H29: 6 | I29: =H29*E29 -> 574.8
B30: Определение радионуклидов хроматомасс-спектрометрическим методом | C30: табл. 70, § 69 | D30: проба | E30: 147.4 | H30: 6 | I30: =PRODUCT(E30,H30) -> 884.4
B31: Итого лабораторных работ: | I31: =SUM(I21:I30) -> 1917
A32: КАМЕРАЛЬНЫЕ РАБОТЫ
B33: Составление инженерно-экологических карт м-ба 1: 25000 при удовлетворительной проходимости | C33: т.10 п.2 | D33: км | E33: 1.7 | F33: 1.3 | H33: 18.5 | I33: =H33*F33*E33 -> 40.885
B34: Описание точек наблюдений при составлении инженерно-экологических карт (МЭД) | C34: т.11 п.2 | D34: 1 точка | E34: 7.5 | F34: 1.15 | G34: 0.3 | H34: 370 | I34: =H34*E34*F34*G34 -> 957.375
B35: Обработка лабораторных анализов | C35: т.86 п.6 | D35: % | E35: 20 | I35: =I31*(E35/100) -> 383.4
B36: Итого камеральных работ: | I36: =I33+I34+I35 -> 1381.66
B37: Составление технического отчёта | C37: т.87 п.1 | D37: % | E37: 21 | I37: =SUM(I36+I18)*(E37/100) -> 706.7025
B38: Итого камеральных работ с учетом районного коэффициента: Новосибирская обл., г.Новосибирск | G38: 1.1 | I38: =SUM(I33:I37)*G38 -> 3817.0248
A39: ПРОЧИЕ РАСХОДЫ
B40: Внутренний транспорт при расстоянии 20-25 км и стоимости полевых работ до 5 тыс. руб. | C40: т.4 п.5 | D40: % | E40: 18.75 | I40: =I18*E40/100 -> 371.92313
...

Sheet №4 ИГИ
A1: ИСПОЛНИТЕЛЬНАЯ СМЕТА № 4
A2: на полевые инженерно-геологические работы
A4: Стадия проектирования | D4: Проектная документация
A5: Наименование строительства | D5: Организация пассажирского сообщения от станции Москва-Октябрьская-Пассажирская до проектируемого транспортно-пересадочного узла "Завидово" через остановочный пункт Путепроводная Октябрьской железной дороги Этап 2. Строительство железнодорожной линии от примыкания к Октябрьской железной дороге до проектируемого ТПУ «Завидово»
A6: Наименование организации | D6: ООО "ДСК"
A7: подрядчика
A8: Наименование изыскательской | D8: ОАО "Сибгипротранс"
A9: организации
A10: № п/п | B10: виды работ | D10: Обоснование стоимости | E10: Расчёт стоимости | O10: Стоимость (рублей)
B11: Наименование | C11: кол-во
A12: 1 | B12: 2 | D12: 3 | E12: 4 | O12: 5
A13: ИНЖЕНЕРНО-ГЕОЛОГИЧЕСКИЕ РАБОТЫ
A14: СБЦ-99 Справочник базовых цен на инженерно-геологические и инженерно-экологические изыскания для строительства (цены приведены к базисному уровню на 01.01.1991г). Москва 1999г
A15: Категория сложности инженерно-геологических условий III (сложная)
A16: Продолжительность неблагоприятного периода 6,5 мес (15-20/X по 1-5/V)
A17: I. ПОЛЕВЫЕ РАБОТЫ
A18: 1 | B18: Инженерно-геологическое рекогносцировочное обследование трассы район II кат.сложности при удовлетворительной проходимости | C18: 29.54 | D18: табл.9, п.2 | J18: =SUM(C18) -> 29.54 | K18: * | L18: 27 | O18: =SUM(J18*L18) -> 797.58
B19: Буровые работы
A20: 2 | B20: Бурение скважин колонковым способом Ø св.160мм глубиной до 15м в грунтах: | D20: табл.17
B21: II категории, п.м. | C21: 654.7 | D21: п.1 | G21: =SUM(C21) -> 654.7 | H21: * | J21: 38.4 | K21: * | L21: 0.9 | O21: =ROUND(G21*J21*L21,0) -> 22626
B22: III категории, п.м. | C22: 730.3 | G22: =SUM(C22) -> 730.3 | H22: * | J22: 42.6 | K22: * | L22: 0.9 | O22: =ROUND(G22*J22*L22,0) -> 28000
B23: Всего метров: | C23: =SUM(C21:C22) -> 1385
B24: К-0,9 бурение без устройства циркуляционной системы | D24: табл.17, прим.
A25: 3 | B25: Бурение скважин колонковым способом Ø до 160мм глубиной св. 15 до 25м в грунтах: | D25: табл.17
B26: III категории, п.м. | C26: 70 | G26: =SUM(C26) -> 70 | H26: * | J26: 36.2 | K26: * | L26: 0.9 | O26: =ROUND(G26*J26*L26,0) -> 2281
B27: Всего метров: | C27: =SUM(C26:C26) -> 70
A28: 4 | B28: Бурение скважин колонковым способом Ø до 160мм глубиной св.25 до 50 м в грунтах: | D28: табл.17
B29: III категории, п.м. | C29: 100 | G29: =SUM(C29) -> 100 | H29: * | J29: 31.3 | K29: * | L29: 0.95 | O29: =ROUND(G29*J29*L29,0) -> 2974
B30: Всего метров: | C30: =SUM(C29:C29) -> 100
B31: Бурение скважин колонковым способом Ø до 160мм глубиной св.50 м в грунтах:
B33: III категории, п.м. | C33: 5 | G33: =SUM(C33) -> 5 | H33: * | J33: 27.5 | K33: * | L33: 0.95 | O33: =ROUND(G33*J33*L33,0) -> 131
B34: К-0,9 К-0,95 бурение без устройства циркуляционной системы | D34: табл.17, прим.
A35: 5 | B35: Гидрогеологические наблюдения при бурении скважин Ø до 160мм. глубиной до 25м | D35: табл.18, п.1 | J35: 911.9 | K35: * | L35: 1.6 | M35: * | N35: 0.6 | O35: =ROUND(J35*L35*N35,0) -> 875
B36: К-0,6 -гидрогеологические наблюдения без "тартания" | D36: Часть 2, Глава 4, п.8
A37: 6 | B37: Гидрогеологические наблюдения при бурении скважин Ø до 160мм. Глубиной св.25 до 50 м | D37: табл.18, п.1 | J37: 110.8 | K37: * | L37: 1.8 | M37: * | N37: 0.6 | O37: =ROUND(J37*L37*N37,0) -> 120
B38: К-0,6 -гидрогеологические наблюдения без "тартания" | D38: Часть 2, Глава 4, п.8
A39: 7 | B39: Гидрогеологические наблюдения при бурении скважин Ø до 160мм. глубиной св.50,0м | D39: табл.18, п.1 | J39: 48.3 | K39: * | L39: 2 | M39: * | N39: 0.6 | O39: =ROUND(J39*L39*N39,0) -> 58
B40: К-0,6 -гидрогеологические наблюдения без "тартания"
A41: 8 | B41: Крепление скважин при бурении Ø до 160мм - 50% | D41: табл.18, п.4 | J41: 1064 | K41: * | L41: 2.1 | M41: * | N41: 0.5 | O41: =ROUND(J41*L41*N41,0) -> 1117
B42: Горнопроходческие работы
...

Sheet №5 ИГФИ
A1: СМ | O1: Форма №2п
A2: С М Е Т А №5
A3: геофизические работы
A5: Стадия проектирования | D5: Проектная документация
A6: Наименование строительства | D6: Организация пассажирского сообщения от станции Москва - Октябрьская - Пассажирская до проектируемого транспортно-пересадочного узла «Завидово» через остановочный пункт Путепроводная Октябрьской железной дороги Этап 2. Строительство железнодорожной линии от примыкания к октябрьской железной дороге до проектируемого тпу «завидово»
A7: Наименование организации заказчика | D7: ООО "ДСК"
A8: Наименование проектной (изыскательской) организации | D8: ОАО "Сибгипротранс"
A9: № п/п | B9: виды работ | D9: № частей, глав, таблиц,пунктов, указаний к разделу или главе Сборника цен | E9: Расчёт стоимости объём строительно-монтажных работ х% : 100 или количества х цена | O9: Стоимость (рублей)
B10: Наименование | C10: кол-во
A11: 1 | B11: 2 | C11: 3 | D11: 4 | E11: 5 | O11: 6
A12: СЦР-82 -Сборник цен на изыскательские работы для капитального строительства
A13: Категория сложности для сейсморазведки, электроразведки - III (глава 16. Геофизические работы. Общие положения)
A14: Категория сложности для определения коррозионной активности грунтов и интенсивности блуждающих токов - II (Глава 16. Геофизические работы. стр. 279)
A15: Продолжительность неблагоприятного периода 6,5 месяцев с 20/X по 5/V
A16: Полевые работы
A17: Сейсморазведка
A18: 1 | B18: Сейсморазведка (сейсмотомография (МПВ, МОВ) 48 канальной сейсмостанцией, при возбуждении колебаний ударами кувалды при шаге наблюдений до 5м. | C18: 192 | D18: таб.258, п.83 | G18: =SUM(C18) -> 192 | I18: * | J18: 10 | K18: * | L18: 1.1 | O18: =ROUND(G18*J18*L18,0) -> 2112
B19: Коэффициенты:
B20: К 1- механические и электрические помехи | C20: 1.1 | D20: Глава 16, п.5
A21: Электроразведочные работы
A22: 2 | B22: Георадарное зондирование , физ.набл. | C22: 4000 | D22: таб. 270, п.1(применительно) | G22: =SUM(C22) -> 4000 | I22: * | J22: 1 | O22: =ROUND(G22*J22,0) -> 4000
A23: 3 | B23: Измерение удельного электирческого сопротивления грунта четырехэлектродной установкой при расстоянии между точками св.100 до 200 м | C23: 150 | D23: таб. 267, п.3. | G23: =SUM(C23) -> 150 | I23: * | J23: 1.5 | K23: * | L23: =SUM(C29) -> 1.32 | O23: =ROUND(G23*J23*L23,0) -> 297
B24: Коэффициенты:
B25: К 1- механические и электрические помехи | C25: 1.1 | D25: Глава 16, п.5
B26: К 2 - переноска оборудования с профиля на профиль на расстояние до 200м | C26: 1.2 | D26: Глава 16, п.6
B27: К 3 - заземление электродов в сухих породах в случае подлива воды | C27: 1 | D27: табл.265, п. 3
B28: К 4 - разность потенциалов до 0,3 мВ, неустойчивые точки ПС | C28: 1 | D28: табл.265, п. 4
B29: Кобщ = | C29: =SUM(C25*C26*C27*C28) -> 1.32
A30: 4 | B30: Измерение разности потенциалов между двумя точками земли при расстоянии до 200м (интенсивность блуждающих токов). Измерение самопишушими приборами при длительности записи до 1 ч, измерение | C30: 18 | D30: табл.283, п.2 | G30: =SUM(C30) -> 18 | I30: * | J30: 15 | K30: * | L30: =SUM(C34) -> 1.1 | O30: =ROUND(G30*J30*L30,0) -> 297
B31: Коэффициенты:
B32: К 1- механические и электрические помехи | C32: 1.1 | D32: Глава 16, п.5
B33: К 2 - расстояние св.200 до 500 м | C33: 1 | D33: табл.283, прим.
B34: Кобщ = | C34: =SUM(C32*C33) -> 1.1
A35: 5 | B35: Вертикальное электрическое зондирование с поверхности земли четырехэлекродной установкой (в модификации электротомографии) Длина установки св 25 до 500 м | C35: =64*3 -> 192 | D35: табл.267, п.4 | G35: 192 | I35: * | J35: 13.5 | K35: * | L35: 1.1 | O35: =ROUND(G35*J35*L35,0) -> 2851
B36: Коэффициенты:
B37: К 1- механические и электрические помехи | C37: 1.1 | D37: Глава 16, п.5
B38: Кобщ = | C38: =C37 -> 1.1
A39: Итого по п.п. 1-5 с учетом коэффициента | D39: прил. к постановлению Госстроя СССР №22 от 01.03.90. Общ.указ
B40: к-1,1 - метрологическое обеспечение единства точности измерений | J40: =SUM(O18:O35) -> 9557 | K40: * | L40: 1.1 | O40: =ROUND(J40*L40,0) -> 10513
A41: 6 | B41: Планово-высотная привязка точек геофизической разведки | C41: =SUM(C18+C30+C35+70) -> 472 | D41: табл.78, п.2, кат III | J41: =SUM(C41) -> 472 | K41: * | L41: 4.2 | O41: =ROUND(J41*L41,0) -> 1982
...

Sheet №6 ПД ПЖ
E1: Форма № 2П
A2: Приложение к _______________________________________________________________
B3: (договору, дополнительному соглашению, наряд-заказу)
A5: СМЕТА №6
A6: на проектные (изыскательские) работы
A8: Стадия проектирования | C8: Проектная и рабочая документация
A9: Наименование строительства | C9: Организация пассажирского движения от станции
C10: Москва-Октябрьская-Пассажирская до проектируемого
C11: ТПУ "Завидово" через остановочный пункт Путепроводная
C12: Октябрьской железной дороги
C13: Этап 2. Строительство железнодорожной линии от примыкания к Октябрьской железной дороге до проектируемого ТПУ «Завидово»
C15: Пути железнодорожные
A16: Наименование проектной
A17: (изыскательской) организации | C17: ОАО "Сибгипротранс"
A19: Наименование организации-
A20: заказчика
A22: №№ п.п. | B22: Характеристика предприятия, здания, сооружения или виды работ | C22: №№ частей, глав, таблиц, $$ и пунктов указаний к разделу или главе Сборника цен на проектные и изыскательские работы для строительства | D22: Расчет стоимости а + вх или объем строительно-монтажных работ х%:100 или количество х цена | E22: Стоимость (тыс.руб.)
A23: 1 | B23: 2 | C23: 3 | D23: 4 | E23: 5
A25: 1 | B25: Новая железная дорога | C25: СБЦПР-2014 г. | D25: (5035000+141500*12,7)* | E25: =ROUND((5035000+141500*12.7)*0.9*0.49,0)/1000 -> 3012.934
B26: (электрическая тяга) | C26: "Железные | D26: *0.9*0,49
B27: Длина - 11,7 км | C27: дороги"
C28: таб.1, п.8, гр. 5,6
B29: Коэффициенты:
B30: Профильный объем земляных | C30: СБЦПР п.2.1.4
B31: работ - 34 тыс.м3/км (3 степень
B32: сложности)
B33: К1 = 0.9 - для 3-ей степени | C33: СБЦПР
B34: К2 = 2+3+5+8+2+5+6+10+8=49% | C34: таб. 51
B36: Итого | E36: =SUM(E25:E35) -> 3012.934
B37: в том числе П | E37: =E36*0.4 -> 1205.1736
B38: в том числе РД | E38: =E36*0.6 -> 1807.7604
B40: Всего с учетом индекса К=5,81 на I квартал 2024г. | C40: Письмо Минстроя России от 07.03.2024 N 13023-ИФ/09 | E40: =E36*5.81 -> 17505.147
B41: в том числе П | E41: =E40*0.4 -> 7002.0586
B42: в том числе РД | E42: =E40*0.6 -> 10503.088
B44: Начальник отдела | D44: А.В. Арбеков

Sheet №7 ПД ИССО
E1: Форма № 2П
A3: Приложение к _______________________________________________________________
B4: (договору, дополнительному соглашению, наряд-заказу)
A6: СМЕТА №7
A8: на проектные (изыскательские) работы
A10: Стадия проектирования | C10: Проектная и рабочая документация
A11: Наименование строительства | C11: Организация пассажирского движения от станции
C12: Москва-Октябрьская-Пассажирская до проектируемого
C13: ТПУ "Завидово" через остановочный пункт Путепроводная
C14: Октябрьской железной дороги
C15: Этап 2. Строительство железнодорожной линии от примыкания к Октябрьской железной дороге до проектируемого ТПУ «Завидово»
C17: Искусственные сооружения
A18: Наименование проектной
A19: (изыскательской) организации | C19: ОАО "Сибгипротранс"
A21: Наименование организации-
A22: заказчика
A24: №№ п.п. | B24: Характеристика предприятия, здания, сооружения или виды работ | C24: №№ частей, глав, таблиц, $$ и пунктов указаний к разделу или главе Сборника цен на проектные и изыскательские работы для строительства | D24: Расчет стоимости а + вх или объем строительно-монтажных работ х%:100 или количество х цена | E24: Стоимость (тыс.руб.)
A25: 1 | B25: 2 | C25: 3 | D25: 4 | E25: 5
A27: 1 | B27: Металлический путепровод | C27: СБЦП-81-2001-16 | D27: (66000+3740*51,3)* | E27: =ROUND((66000+3740*51.3)*1.1*0.95*1.1,0)/1000 -> 296.412
B28: по схеме 1х44 м | C28: "Искусственные | D28: *0,95*1,1*1,1
B29: Длина - 51,3 м | C29: сооружения"
C30: таб.1, п.6.3, гр. 6,7
B31: Коэффициенты:
B32: К1 = 0,95 - на высоту опор; | C32: СБЦП п.2.1.10
B33: К2 = 1,1 - для индивидуальных | C33: СБЦП п.2.1.15
B34: опорных частей;
B35: К3 = 1,1 - на водоотвод | C35: СБЦП п.2.1.16
A37: 2 | B37: СВСиУ для строительства | C37: СБЦП-81-2001-16 | D37: п.1*0,2 | E37: =ROUND((E27)*0.2,0) -> 59
B38: путепровода | C38: "Искусственные
C39: сооружения"
C40: таб.5, п.4, гр. 5
A42: 3 | B42: Водопропускные трубы (КЖБТ) | C42: СБЦП-81-2001-16 | D42: (6600+290*20)*1,1*16 | E42: =ROUND((6600+290*22.2)*1.1*16,0)/1000 -> 229.469
B43: Ср. длина 20 метров | C43: "Искусственные
B44: Количество - 16 штук | C44: сооружения"
C45: таб.2, п.1.4, гр. 4,5
B46: Коэффициенты:
B47: К1 = 1,1 - на замену грунта; | C47: СБЦП п.2.1.28
A49: 4 | B49: Гидравлические расчеты для | C49: СБЦП-81-2001-16 | D49: п.3*0,055 | E49: =ROUND((E42)*0.055,0) -> 13
B50: труб | C50: "Искусственные
C51: сооружения"
...

Sheet №8 ПД Здания
A1: Приложение к | E1: форма №2п
B2: (договору, дополнительному соглашению)
A3: Смета №8
A4: на проектные и изыскательские работы.
B6: Стадия проектирования и | C6: Проектная и рабочая документация.
B7: наименование строительства: | C7: Организация пассажирского сообщения от станции Москва-Октябрьская-Пассажирская до проектируемого транспортно-пересадочного узла "Завидово" через остановочный пункт Путепроводная Октябрьской железной дороги. Этап 2. Строительство железнодорожной линии от примыкания к Октябрьской железной дороге до проектируемого ТПУ «Завидово»
C11: Здания и сооружения.
B12: Наименование проектной | C12: ОАО "Сибгипротранс"
B13: (изыскательской) организации
B14: Наименование организации- | C14: ООО "ДСК"
B15: заказчика
A16: №№ п.п. | B16: Характеристика предприятий, зданий, сооружений или виды работ | C16: №№ частей,глав, таблиц,и пунктов указаний к разделу или главе сборника цен на проектно -изыскательские работы для строительства | D16: Расчет стоимости а+вх или объем СМРх% : 100, или количество х цена. | E16: стоимость (тыс.руб.)
A17: 1 | B17: 2 | C17: 3 | D17: 4 | E17: 5
B18: ТПУ Завидово
A19: 1 | B19: Генеральный план территории. Расчетная площадь территории - 4 га | C19: СБЦ-2004 "Объекты промышленности химических волокон" тб.3 п.3.1. | D19: 30,938*4 | E19: =ROUND(30.938*4,2) -> 123.75
A20: =A19+1 -> 2 | B20: Вокзал на 200 пассажиров К=1,2 - на кондиционирование (п.2.10 СБЦП81-2001-09) К=1,15 - на грунтовые условия - подтапливаемая территория (п.6 Общих указаний по применению СБЦПР) | C20: СБЦП81-2001-09 "Железные дороги" тб.7 п. 1.2 | D20: (404700+3100*200)*1,2*1,15 | E20: =ROUND((404.7+3.1*250)*1.2*1.15,2) -> 1627.99
A21: =A20+1 -> 3 | B21: Платформа площадью 3080 м2 К=1,15 - на грунтовые условия - подтапливаемая территория (п.6 Общих указаний по применению СБЦПР) | C21: СБЦП81-2001-09 "Железные дороги" тб.7 п.6.3 | D21: (113000+30*308)*1,15 | E21: =ROUND((113+0.03*308)*1.15,2) -> 140.58
A22: =A21+1 -> 4 | B22: Навесы К=1,15 - на грунтовые условия - подтапливаемая территория (п.6 Общих указаний по применению СБЦПР) | C22: СБЦП81-2001-09 "Железные дороги" тб.7 п. 4.2 | D22: (122500+20*1000)*1,15 | E22: =ROUND((122.5+0.02*1000)*1.15,2) -> 163.88
A23: =A22+1 -> 5 | B23: Центральный лестничный вход на платформу с пандусом | C23: СБЦ-2014 "Железные дороги тб.10 п.18 | D23: (97180+680*10)*1,15 | E23: =ROUND((97.18+0.68*10)*1.15,2) -> 119.58
A24: =A23+1 -> 6 | B24: Турникетный павильон К=1,15 - на грунтовые условия - подтапливаемая территория (п.6 Общих указаний по применению СБЦПР) | C24: СБЦП81-2001-09 "Железные дороги" тб.7 п. 3 | D24: (259,9+0,48*120)*1,15*1,2 | E24: =ROUND((259.9+0.48*120)*1.15,2) -> 365.13
A25: =A24+1 -> 7 | B25: Периметровое ограждение территории Расчетная длина ограждения 1,5км | C25: СБЦ-2014 "Железные дороги тб.10 п.9.1 | D25: (14,950+18,360*1,5)*1,15 | E25: =ROUND((14.95+18.36*1.5)*1.15,2) -> 48.86
A26: =A25+1 -> 8 | B26: Подпорная стенка 500 м | C26: СБЦ-2014 "Железные дороги тб.10 п.11.4 | D26: (319+2,75*100)*1,15 | E26: =ROUND((319+2.75*100)*1.15,2) -> 683.1
A27: =A26+1 -> 9 | B27: Шумозащитный экран | C27: СБЦ-2014 "Железные дороги тб.10 п.10.1 | D27: 260*1,15 | E27: =ROUND(260*1.15,2) -> 299
A28: =A27+1 -> 10 | B28: Фундамент КТП, 2 шт | C28: СБЦ - 2014 "Железные дороги тб.45 п.4 | D28: 43,2*2*1,15 | E28: =ROUND(43.2*2*1.15,2) -> 99.36
A29: =A28+1 -> 11 | B29: Фундамент модульный пост ЭЦ | C29: СБЦ - 2014 "Железные дороги тб.45 п.4 | D29: (43,2+43*0,1*9)*1,15 | E29: =ROUND((43.2+43*0.1*9)*1.15,2) -> 94.19
A30: =A29+1 -> 12 | B30: Фундамент пункта питания | C30: СБЦ - 2014 "Железные дороги тб.45 п.4 | D30: (43,2+43*0,1*2)*1,15 | E30: =ROUND((43.2+43*0.1*2)*1.15,2) -> 59.57
A31: =A30+1 -> 13 | B31: Автомобильная стоянка | C31: СБЦ-2014 "Железные дороги тб.10 п.12.1 | D31: 310 | E31: =ROUND(310,2) -> 310
A32: =A31+1 -> 14 | B32: Опора поездной радиосвязи, 12 м | C32: СБЦ-81-2001-02 "Объекты связи" тб.18 п.1 | D32: (58,04+0,398*12)*1,15 | E32: =ROUND((58.04+0.398*12)*1.15,2) -> 72.24
B33: Блок пост на 10 км
A34: =A32+1 -> 15 | B34: Генеральный план территории. Расчетная площадь территории - 1 га | C34: СБЦ-2004 "Объекты промышленности химических волокон" тб.3 п.3.1. | D34: 30,938*1 | E34: =ROUND(30.938*1,2) -> 30.94
A35: =A34+1 -> 16 | B35: Фундамент модульный пост ЭЦ | C35: СБЦ - 2014 "Железные дороги тб.45 п.4 | D35: (43,2+43*0,1*9)*1,15 | E35: =ROUND((43.2+43*0.1*9)*1.15,2) -> 94.19
A36: =A35+1 -> 17 | B36: Фундамент КТП | C36: СБЦ - 2014 "Железные дороги тб.45 п.4 | D36: 43,2*1,15 | E36: =ROUND(43.2*1.15,2) -> 49.68
A37: =A36+1 -> 18 | B37: Опора поездной радиосвязи, 12 м | C37: СБЦ-81-2001-02 "Объекты связи" тб.18 п.1 | D37: (58,04+0,398*50)*1,15 | E37: =ROUND((58.04+0.398*50)*1.15,2) -> 89.63
B38: Мачта связи на Канаковском шоссе
A39: =A37+1 -> 19 | B39: Генеральный план территории. Расчетная площадь территории - 1 га | C39: СБЦ-2004 "Объекты промышленности химических волокон" тб.3 п.3.1. | D39: 30,938*1 | E39: =ROUND(30.938*1,2) -> 30.94
A40: =A39+1 -> 20 | B40: Опора поездной радиосвязи, 50 м | C40: СБЦ-81-2001-02 "Объекты связи" тб.18 п.1 | D40: (58,040+0,398*50)*1,15 | E40: =ROUND((58.04+0.398*50)*1.15,2) -> 89.63
B41: Ст.Конаковский мох
A42: =A40+1 -> 21 | B42: Генеральный план территории. Расчетная площадь территории - 1 га | C42: СБЦ-2004 "Объекты промышленности химических волокон" тб.3 п.3.1. | D42: 30,938*1 | E42: =ROUND(30.938*1,2) -> 30.94
A43: =A42+1 -> 22 | B43: Фундамент модульный пост ЭЦ | C43: СБЦ - 2014 "Железные дороги тб.45 п.4 | D43: (43,2+43*0,1*9)*1,15 | E43: =ROUND((43.2+43*0.1*9)*1.15,2) -> 94.19
A44: =A43+1 -> 23 | B44: Фундамент КТП | C44: СБЦ - 2014 "Железные дороги тб.45 п.4 | D44: 43,2*1,15 | E44: =ROUND(43.2*1.15,2) -> 49.68
...

Sheet №9 ПД Водоснабжение
A1: Приложение к | E1: форма №2п
B2: (договору, дополнительному соглашению)
A3: Смета №9
A4: на проектные и изыскательские работы.
B6: Стадия проектирования и | C6: Проектная и рабочая документация.
B7: наименование строительства: | C7: Организация пассажирского сообщения от станции Москва-Октябрьская-Пассажирская до проектируемого транспортно-пересадочного узла "Завидово" через остановочный пункт Путепроводная Октябрьской железной дороги. Этап 2. Строительство железнодорожной линии от примыкания к Октябрьской железной дороге до проектируемого ТПУ «Завидово»
C11: Водоснабжение и водоотведение
B12: Наименование проектной | C12: ОАО "Сибгипротранс"
B13: (изыскательской) организации
B14: Наименование организации- | C14: ООО "ДСК"
B15: заказчика
A16: №№ п.п. | B16: Характеристика предприятий, зданий, сооружений или виды работ | C16: №№ частей,глав, таблиц,и пунктов указаний к разделу или главе сборника цен на проектно -изыскательские работы для строительства | D16: Расчет стоимости а+вх или объем СМРх% : 100, или количество х цена. | E16: стоимость (тыс.руб.)
A17: 1 | B17: 2 | C17: 3 | D17: 4 | E17: 5
A18: 1 | B18: Хозяйственно-питьевой водопровод 0,1 км | C18: СБЦ-2015 "Объекты водоснабжения и канализации" тб.3 п.1. | D18: (64940+34770*0,1)*1,1 | E18: =ROUND((64940+34770*0.1)*1.1,0)/1000 -> 75.259
A19: =A18+1 -> 2 | B19: Водомерный узел ,встроенный | C19: СБЦ-2008 Городские инж сооружения и коммуникации, табл. 6 п.13 | D19: 77500 | E19: =ROUND(77500,0)/1000 -> 77.5
A20: =A19+1 -> 3 | B20: Противопожарные резервуары запаса воды в районе блок-поста 10км, ёмкостью 0,01тыс. М3 (2шт) К=1,5 на 2-й резервуар | C20: СБЦ-2015 "Объекты водоснабжения и канализации" тб.5 п.10. | D20: (21960+79880*0,01)*1,5 | E20: =ROUND((21960+79880*0.01)*1.5,0)/1000 -> 34.138
A21: =A20+1 -> 4 | B21: Противопожарный водопровод 0,1 км | C21: СБЦ-2015 "Объекты водоснабжения и канализации" тб.3 п.1. | D21: (64940+34770*0,1)*1,1 | E21: =ROUND((64940+34770*0.1)*1.1,0)/1000 -> 75.259
A22: =A21+1 -> 5 | B22: Сети хоз.бытовой канализации 0,05км К=1,1 - на пластиковые трубы | C22: СБЦ-2015 "Объекты водоснабжения и канализации" тб.8 п.1. | D22: (101100+16890*0,05)*1,1 | E22: =ROUND((101100+16890*0.05)*1.1,0)/1000 -> 112.139
A23: =A22+1 -> 6 | B23: Сети ливневой канализации 0,3км К=1,1 - на пластиковые трубы | C23: СБЦ-2015 "Объекты водоснабжения и канализации" тб.8 п.1. | D23: (101100+16890*0,3)*1,1 | E23: =ROUND((101100+16890*0.3)*1.1,0)/1000 -> 116.784
A24: =A23+1 -> 7 | B24: Станция перекачки загрязненных стоков | C24: СБЦ-2015 "Объекты водоснабжения и канализации" тб.8 п.1. | D24: (147380+242530*0,15) | E24: =ROUND((147380+242530*0.15),0)/1000 -> 183.76
A25: =A24+1 -> 8 | B25: Очистные сооружения ливневых стоков К=0,7 - на привязку с внесением изменений | C25: СБЦ-2015 "Объекты водоснабжения и канализации" тб.10 п.14. | D25: (414910+34860*0,15)*0,7 | E25: =ROUND((414910+34860*0.15)*0.7,0)/1000 -> 294.097
A26: =A25+1 -> 9 | B26: Сети канализации, напорные длиной 0,5 км | C26: СБЦ-2015 "Объекты водоснабжения и канализации" тб.3 п.1. | D26: (64940+34770*0,5) | E26: =ROUND((64940+34770*0.5),0)/1000 -> 82.325
A27: =A26+1 -> 10 | B27: Противопожарные резервуары запаса воды в районе ст.Канаковский мох, ёмкостью 0,01тыс. М3 (2шт) К=1,5 на 2-й резервуар | C27: СБЦ-2015 "Объекты водоснабжения и канализации" тб.5 п.10. | D27: (21960+79880*0,01)*1,5 | E27: =ROUND((21960+79880*0.01)*1.5,0)/1000 -> 34.138
A28: =A27+1 -> 11 | B28: Противопожарный водопровод 0,1 км | C28: СБЦ-2015 "Объекты водоснабжения и канализации" тб.3 п.1. | D28: (64940+34770*0,1)*1,1 | E28: =ROUND((64940+34770*0.1)*1.1,0)/1000 -> 75.259
A29: =A28+1 -> 12 | B29: Очистные сооружения ливневых стоков на перегоне, 10 шт К=0,1 - на привязку с внесением изменений | C29: СБЦ-2015 "Объекты водоснабжения и канализации" тб.10 п.14. | D29: (414910+34860*0,15)*0,1*10 | E29: =ROUND((414910+34860*0.15)*0.1*10/1000,3) -> 420.139
A30: =A28+1 -> 12 | B30: ВСЕГО в базовых ценах | E30: =SUM(E18:E29) -> 1580.797
B31: Проектная документация | D31: =CONCATENATE(E25,"*0,4") -> 294,097*0,4 | E31: =E30*0.4 -> 632.3188
B32: Проектная документация | D32: =CONCATENATE(E30,"*0,6") -> 1580,797*0,6 | E32: =E30*0.6 -> 948.4782
A34: =A30+1 -> 13 | B34: на 1кв. 2024 | C34: Письмо Минстроя России от 07.03.2024 N 13023-ИФ/09 | D34: =CONCATENATE(E30,"*5,81") -> 1580,797*5,81 | E34: =E30*5.81 -> 9184.4306
B35: Проектная документация | D35: =CONCATENATE(E30,"*0,4") -> 1580,797*0,4 | E35: =E34*0.4 -> 3673.7722
B36: Проектная документация | D36: =CONCATENATE(E34,"*0,6") -> 9184,43057*0,6 | E36: =E34*0.6 -> 5510.6583
B38: Начальник отдела | D38: М.А. Чурин
B40: Составил | D40: М.А. Чурин

Sheet №10 ПД ЭС
E1: Приложение №________
E2: к Договору №______________
E3: от "____"_____________201_
B5: СМЕТА № 10
B6: на проектные работы
B8: Наименование предприятия, | C8: Организация пассажирского сообщения от станции Москва-Октябрьская-Пассажирская до проектируемого ТПУ "Завидово" через остановочный пункт Путепроводная Октябрьской железной дороги Этап 2. Строительство железнодорожной линии от примыкания к Октябрьской железной дороге до проектируемого ТПУ «Завидово»
B9: здания, сооружения
B12: Стадия проектных работ | C12: Проектная документация
B14: Наименование работ | C14: Электроснабжение и электросовещение (ТПУ "Завидово")
B16: Наименование проектной организации | C16: ОАО "Сибгипротранс"
B18: Наименование организации-заказчика | C18: ООО "ДСК"
C20: №№ частей, глав,
C21: таблиц и пунктов | D21: Расчет стоимости -
A22: №№ | B22: Характеристика предприятия, здания, | C22: Указаний к разделу | D22: а + вх; или - объем | E22: Стоимость
A23: п/п | B23: сооружения, или вида работ | C23: или главе Сборника | D23: строительно - монт- | E23: (руб.)
C24: цен на проектные | D24: тажных работ х
C25: и изыскательские | D25: х % : 100; или
C26: работы для строи- | D26: количество х цена
C27: тельства
A28: 1 | B28: 2 | C28: 3 | D28: 4 | E28: 5
B29: Пункт питания ТПУ Завидово
B30: Кабельные сети 10,0 кВ ТПУ Завидово | C30: СБЦП 81-2001-09 | D30: 11960*1 | E30: =11960*1 -> 11960
B31: Протяженность - 0,040 км | C31: Железнодорожные
C32: дороги
C33: 2014г
C34: табл. 17, п.1
A36: 2 | B36: Высоковольтные линии электроснабжения ВЛЗ-1 10 кВ | C36: СБЦП 81-2001-09 | D36: 133000+0,010*2270 | E36: =133000+0.01*2270 -> 133022.7
B37: тункт питания ТПУ Завидово | C37: Железнодорожные
B38: Протяженность - 0,010 км | C38: дороги
C39: 2014г
C40: табл. 21, п.1.1
A42: 3 | B42: Установка разьединителя типа Тесла-1-10/400 УХЛ1 | C42: СБЦП 81-2001-07 | D42: 11220*1*1 | E42: =11220*1*1 -> 11220
B43: Количество - 1 | C43: Коммунальные
C44: инженерные сети и
C45: сооружения
C46: 2012г
C47: табл. 37, п.12
C48: (применительно)
A50: 4 | B50: Расчет заземления ( 1 расчет) | C50: СБЦП 81-2001-07 | D50: 1740*1*0,8 | E50: =1740*1*0.8 -> 1392
C51: Коммунальные
...

Sheet №11 УГТ ПД ЭС Тяговые
A1: «Адепт: Проект в 16.4» © ООО «Адепт» | D1: форма №2П от 08.04.2024г к Договору от 08.04.2024 г.
A3: Смета №11
A4: на проектные (изыскательские) работы
A6: по объекту: | D6: Организация пассажирского сообщения от станции Москва -Октябрьская-Пассажирская до проектируемого ТПУ "Завидово" через остановочный пункт Путепроводная Октябрьской железной дороги Этап 2. Строительство железнодорожной линии от примыкания к Октябрьской железной дороге до проектируемого ТПУ «Завидово»
A8: Наименование предприятия, здания, сооружения, стадии проектирования, этапа, вида проектных или изыскательских работ | D8: Система электроснабжения
A10: Наименование проектной (изыскательской) организации | D10: ОАО "Сибгипротранс"
A12: Наименование организации заказчика | D12: ООО "ДСК"
A14: № пп | B14: Характеристика предприятия, здания, сооружения или виды работ | D14: Номер частей, глав, таблиц, процентов, параграфов и пунктов указаний к разделу Справочника базовых цен на проектные и изыскательские работы для строительства | H14: Расчет стоимости: (a+bx)*Ki, или (объем строительно-монтажных работ) * проц./100 или количество x цена | I14: Стоимость, тыс. руб.
A15: 1 | B15: 2 | D15: 3 | H15: 4 | I15: 5
A16: 1 | B16: Раздел | D16: ЭЧЭ-7 Решетниково
A17: 1.1 | B17: Закрытое РУ 6-10 кВ и РУ ВЛ СЦБ с установкой функциональных блоков заводского изготовления | D17: Железные дороги. 2014 г. Таблица 15. Здания и сооружения тяговых подстанций, п.13.1 A=175.66 тыс.руб; B=25.07 тыс.руб; Осн. показ. Х=4 (1 блок) Количество = 1 | H17: (A + B * Xзад) * Количество * Кст * K1 (175.66 тыс.руб + 25.07 тыс.руб * 4) * 1 * 0.8 * 1.3 | I17: 286.9776
B18: Коэффициенты
D19: Кст = 0.8
B20: Коэффициент на переустройство | D20: K1 = 1.3
A21: 1.2 | B21: Закрытая установка трансформатора СЦБ или ТСН напряжением 10(6)/0,4-0,23 кВ. | D21: Железные дороги. 2014 г. Таблица 15. Здания и сооружения тяговых подстанций, п.14.1 A=9.55 тыс.руб; B=0.75 тыс.руб; Осн. показ. Х=1 (1 трансформатор) Количество = 2 | H21: (A + B * Xзад) * Количество * Кст * K1 (9.55 тыс.руб + 0.75 тыс.руб * 1) * 2 * 0.6 * 1.3 | I21: 16.068
B22: Коэффициенты
D23: Кст = 0.6
B24: Коэффициент на переустройство | D24: K1 = 1.3
A25: 1.3 | B25: Общие устройства и сооружения для пунктов группировки | D25: Железные дороги. 2014 г. Таблица 15. Здания и сооружения тяговых подстанций, п.13.1 A=24.58 тыс.руб; Количество = 1 (1 объект) | H25: A * Количество * Кст * K1 24.58 тыс.руб * 1 * 0.8 * 1.3 | I25: 25.5632
B26: Коэффициенты
D27: Кст = 0.8
B28: Коэффициент на переустройство | D28: K1 = 1.3
A29: 1.4 | B29: Подстанция 35/6-10 кВ со схемой РУ в виде одной рабочей секционированной выключателем системой шин | D29: Железные дороги. 2014 г. Таблица 16. Релейная защита тяговых подстанций, п.1.1 A=126 тыс.руб; Количество = 1 (1 подстанция) | H29: A * Количество * Кст * K1 * K2 126 тыс.руб * 1 * 0.9 * 2 * 1.5 | I29: 340.2
B30: Коэффициенты
D31: Кст = 0.9
B32: При использовании аппаратуры на микропроцессорной технике базовая цена определяется с применением коэффициента | D32: K1 = 2
B33: При выполнении работ по реконструкции РЗА элементов действующих ТП вводится повышающий коэффициент | D33: K2 = 1.5
A34: 1.5 | B34: Диспетчерское управление энергетическими объектами (электростанциями, подстанциями). Распределительная электросеть. | D34: Железные дороги. 2014 г. Таблица 20. Диспетчерское управление устройств электроснабжения и объектов, приравненных к ним, п.1.2 A=0.55 тыс.руб; Количество = 1 (1 КП) | H34: A * Количество * Кст 0.55 тыс.руб * 1 * 0.65 | I34: 0.3575
B35: Коэффициенты
D36: Кст = 0.65
A37: 1.6 | B37: Устройства телемеханики КП. Объекты ТС. | D37: Железные дороги. 2014 г. Таблица 20. Диспетчерское управление устройств электроснабжения и объектов, приравненных к ним, п.2.1 A=0.7 тыс.руб; Количество = 2 (4 объекта) | H37: A * Количество * Кст 0.7 тыс.руб * 2 * 0.77 | I37: 1.078
B38: Коэффициенты
D39: Кст = 0.77
A40: 1.7 | B40: Устройства телемеханики КП. Объекты ТУ. | D40: Железные дороги. 2014 г. Таблица 20. Диспетчерское управление устройств электроснабжения и объектов, приравненных к ним, п.2.2 A=1.16 тыс.руб; Количество = 2 (4 объекта) | H40: A * Количество * Кст 1.16 тыс.руб * 2 * 0.77 | I40: 1.7864
B41: Коэффициенты
D42: Кст = 0.77
A43: 1.8 | B43: Устройства телемеханики КП. Объекты ТИ. | D43: Железные дороги. 2014 г. Таблица 20. Диспетчерское управление устройств электроснабжения и объектов, приравненных к ним, п.2.3 A=2.47 тыс.руб; Количество = 2 (4 объекта) | H43: A * Количество * Кст 2.47 тыс.руб * 2 * 0.77 | I43: 3.8038
B44: Коэффициенты
D45: Кст = 0.77
A46: 1.9 | B46: Устройства телемеханики сторона (ПУ). Объекты ТС. | D46: Железные дороги. 2014 г. Таблица 20. Диспетчерское управление устройств электроснабжения и объектов, приравненных к ним, п.4.1 A=0.95 тыс.руб; Количество = 1 (8 объектов) | H46: A * Количество * Кст 0.95 тыс.руб * 1 * 0.7 | I46: 0.665
...

Sheet №12 УГТ ПД КС
E1: Форма № 2П
B2: Смета № 12
B3: на проектные (изыскательские) работы
B5: Наименование стройки, стадии проектирования, вида проектных и изыскательских работ. | D5: Организация пассажирского сообщения от станции Москва-Октябрьская-Пассажирская до проектируемого ТПУ "Завидово" через остановочный пункт Путепроводная Октябрьской железной дороги Этап 2. Строительство железнодорожной линии от примыкания к Октябрьской железной дороге до проектируемого ТПУ «Завидово» Контактная сеть, ВЛ10 кВ, волновод, ВОК и ДУ Проектная документация. КС
B6: Наименование проектно- изыскательской организации | D6: ОАО "Сибгипротранс"
B8: Наименование организации- заказчика | D8: ООО "ДСК"
B10: № пп | C10: Наименование предприятия, здания,сооружения,вида работ. Показатели объёмов, мощности, производительности и др. | D10: Сборники (Справочники) цен, разделы,таблицы, пункты,обоснования коэффициентов | E10: Расчёт стоимости | F10: Стоимость (тыс.руб.)
B11: 1 | C11: 2 | D11: 3 | E11: 4 | F11: 5
D12: Справочник базовых цен на проектные работы в строительстве. СБЦП 81-2001-09 Железные дороги Москва 2014. табл. 12 п.1.2
B13: 1 | C13: Контактная сеть при развернутой длине электрифицируемых путей свыше 10 до 30 км. Участок Блок-пост - Завидово, развернутая длина контактной сети 13 км | D13: - " - табл. 12 п.1.2 | E13: (110+3.9*13.0)*1.1*1.2 | F13: =(110+3.9*13)*1.1*1.2 -> 212.124
E14: 1,1-коэф. для электрификации на постоянном токе (здесь и далее)
E17: 1,2 - коэф. Прохождения трассы в кривых свыше 25% до 50%
B18: 2 | C18: Переустройство контактной сети при развернутой длине электрифицируемых путей до 10 км. Участок Решетниково - Блок-пост, развернутая длина контактной сети 10 км | D18: - " - табл. 12 п.1.1 | E18: (108+4,1*10.0)*1.1*1.1 | F18: =(108+4.1*10)*1.1*1.1 -> 180.29
E19: 1,1- в зависимости от объема переустройства (на всем протяжении перегона в данном случае) вводится повышающий коэффициент, глава 2.2, п. 2.2.2 (здесь и далее)
B20: 3 | C20: Усиливающий провод 3 кВ на опорах контактной сети при длине линии 12 км. Участок Блок-пост - Завидово | D20: - " - табл. 12 п.4.3 | E20: (6.3+0.9*12.0)*1.1*1.2 | F20: =(6.3+0.9*12)*1.1*1.2 -> 22.572
B21: 4 | C21: Переустройство усиливающего провода 3 кВ на опорах контактной сети при длине линии 9,5 км. Участок Решетниково - Блок-пост | D21: - " - табл. 12 п.4.2 | E21: (5.3+1.0*9.5)*1.1*1.1 | F21: =(5.3+1*9.5)*1.1*1.1 -> 17.908
B22: 5 | C22: Питающие фидера 3 кВ на опорах контактной сети при длине линии 9,5 км. Участок Решетниково-Блок-пост | D22: - " - табл. 12 п.4.2 | E22: (5.3+1.0*9.5)*1.1*1.1* 1.1 | F22: =(5.3+1*9.5)*1.1*1.1 -> 17.908
B23: 6 | C23: ВЛ 10 кВ ПЭ по опорам контактной сети при длине линии 12 км. Участок Блок-пост - Завидово | D23: - " - табл. 12 п.4.3 | E23: (6.3+0.9*12.0)*1.1*1.1*1.2 | F23: =(6.3+0.9*12)*1.1*1.1*1.2 -> 24.8292
E24: 1.1-коэф. на применение провода СИП.
B25: 7 | C25: Переустройство волновода по опорам контактной сети при длине линии 9,5 км. Участок Решетниково - Блок-пост | D25: - " - табл. 12 п.4.2 | E25: (5.3+1.0*9.5)*1.1*1.1 | F25: =(5.3+1*9.5)*1.1*1.1 -> 17.908
B26: 8 | C26: Волновод по опорам контактной сети при длине линии 12 км. Участок Блок-пост - Завидово | D26: - " - табл. 12 п.4.3 | E26: (6.3+0.9*12.0)*1.1 | F26: =(6.3+0.9*12)*1.1 -> 18.81
B27: 9 | C27: Кабельная линия связи ОАО "РЖД", подвешиваемым на опорах контактной сети при длине 12 км. Участок Блок-пост - Завидово | D27: -"- Таблица 38 п.5 | E27: (78.13+6.25*12.0)*1.1*0.9 | F27: =(78.13+6.25*12)*1.1*0.9 -> 151.5987
D28: Указания к таблице 38 п.2.4.1 | E28: К=0.9 коэффициент при подвеске ВОК опорах контактной сети
B29: 10 | C29: Подключение ПС к контактной сети | D29: - " - табл. 12 п.23 | E29: 22*1.1 | F29: =22*1.1 -> 24.2
B30: 11 | C30: Расчет изгибающих моментов промежуточных опор (27 опор). Участок Блок-пост - Завидово. | D30: - " - табл. 12 п.16.1 | E30: (11.5+0.9*27)*2*1.1 | F30: =(11.5+0.9*27)*2*1.1 -> 78.76
B31: 12 | C31: Расчет изгибающих моментов промежуточных опор (10 опор). Участок Решетниково - Блок-пост | D31: - " - табл. 12 п.16.1 | E31: (11.5+0.9*10)*2*1.1 | F31: =(11.5+0.9*10)*2*1.1 -> 45.1
B32: 13 | C32: Расчет изгибающих моментов переходных опор (5 опор). Участок Блок-пост - Завидово | D32: - " - табл. 12 п.16.3 | E32: (16.5+1.48*5)*2*1.1 | F32: =(16.5+1.48*5)*2*1.1 -> 52.58
B33: 14 | C33: Расчет изгибающих моментов переходных опор (2 опоры). Участок Решетниково - Блок-пост | D33: - " - табл. 12 п.16.3 | E33: (16.5+1.48*2)*2*1.1 | F33: =(16.5+1.48*2)*2*1.1 -> 42.812
B34: 15 | C34: Расчет изгибающих моментов анкерных опор (3 опоры). Участок Блок-пост - Завидово | D34: - " - табл. 12 п.16.2 | E34: (16.5+1.48*3)*2*1.1 | F34: =(16.5+1.48*3)*2*1.1 -> 46.068
B35: 16 | C35: Расчет изгибающих моментов анкерных опор (3 опоры). Участок Решетниково - Блок-пост | D35: - " - табл. 12 п.16.2 | E35: (16.5+1.48*3)*2*1.1 | F35: =(16.5+1.48*3)*2*1.1 -> 46.068
B36: 17 | C36: Расстановка концевых опор в районе тяговой подстанции (3 опоры). Участок Решетниково-Блок-пост | D36: - " - табл. 12 п.25.2 | E36: (16.5+1.48*3)*2*1.1 | F36: =(16.5+1.48*3)*2*1.1 -> 46.068
