Workbook

Sheet Лист1
B3: Показатель | C3: Значение
B4: Стоимость рабочей документации 1 этап по ГК | C4: 3301168 | J4: ССРСС | N4: Смета контракта | R4: Пересчет | W4: Смета № 7 - Переустройство сетей связи | AA4: Смета № 8 - Переустройство линий электроснабжения | AE4: Смета № 9 - Переустрйство сетей газоснабжения
B5: Стоимость рабочей документации 1 этап по ССРСС | C5: =3205790 -> 3205790 | J5: 1 этап | N5: 1 этап | R5: СМР + Рабочка | S5: 88421722 | W5: 1 | X5: =(2000+148*164)*1.05 -> 27585.6 | Y5: Том 1 | AA5: 1 | AB5: =8265+620*41 -> 33685 | AE5: 1 | AF5: =5221+137561*0.25 -> 39611.25
B6: Стоимость рабочей документации по сметным расчетам | C6: =X26+AF10+AB10 -> 3205790.2 | J6: Рабочая документация | K6: 3205790 | N6: Рабочая документация | O6: 3301186 | R6: С дефлятором | S6: 1.0656529e+08 | W6: 2 | X6: =14450*1.05 -> 15172.5 | Y6: Том 2 | AA6: 2 | AB6: =9090*5 -> 45450 | AE6: 2 | AF6: =5221+137561*0.13 -> 23103.93
B7: Дефлятор (по Пересчету цены ГК) | C7: =S7 -> 1.2051936 | R7: КЭФ Дефлятор | S7: =S6/S5 -> 1.2051936 | W7: 3 | X7: =(750+137*157)*1.05 -> 23371.95 | Y7: Том 5 | AA7: 3 | AB7: 2132 | AE7: Всего | AF7: =SUM(AF5:AF6) -> 62715.18
B8: Понижающий (по Пересчету цены ГК) | C8: =S11 -> 0.85442868 | N8: Кэф пересчета | O8: =O6/K6 -> 1.0297574 | W8: 4 | X8: =15850*1.05 -> 16642.5 | Y8: Том 5 | AA8: Всего | AB8: =SUM(AB5:AB7) -> 81267 | AE8: кэф текущих цен | AF8: =339.92/62.72 -> 5.4196429
B9: Общий кэф (по пересчету цены ГК) | C9: =C7*C8 -> 1.029752 | R9: Стоимость всего (без ПИР) | S9: 6.9499705e+09 | W9: 5 | X9: =15850*1.1*1.05 -> 18306.75 | Y9: Том 6 | AA9: в текущих ценах (кэф 5,42) | AB9: =ROUND(AB8*5.42,2) -> 440467.14 | AE9: в текущих ценах | AF9: =ROUND(AF7*AF8,2) -> 339893.88
B10: Общий кэф (ГК на стоимость по ССРСС) | C10: =C4/C6 -> 1.0297517 | R10: С учетом понижающего | S10: 5938254100 | W10: 6 | X10: =15850*1.05 -> 16642.5 | Y10: Том 3 | AA10: в том числе стадия "Р" | AB10: =AB9*0.6 -> 264280.28 | AE10: в том числе стадия "Р" | AF10: =ROUND(AF9*0.6,2) -> 203936.33
R11: КЭФ понижающий | S11: =S10/S9 -> 0.85442868 | W11: 7 | X11: =(31000*1.05*1.2)+(31000*1.05*1.2*0.35)*2 -> 66402 | Y11: Том 1 | AA11: с кэф пересчета | AB11: =ROUND(AB10*C10,2) -> 272143.08 | AC11: 272143 | AD11: =AB11-AC11 -> 0.08 | AE11: с кэф пересчета | AF11: =ROUND(AF10*C10,2) -> 210003.79 | AG11: 210017 | AH11: =AF11-AG11 -> -13.21
R12: Итоговый КЭФ | S12: =S7*S11 -> 1.029752 | W12: 8 | X12: =(31000*1.05*1.2*1.2)*3 -> 140616 | Y12: Том 1
W13: 9 | X13: =(31000*1.05*1.2) -> 39060 | Y13: Том 2
W14: 10 | X14: =(31000*1.05*1.2)+(31000*1.05*1.2*0.35)*2 -> 66402 | Y14: Том 5
B15: Стоимость РД 2 этап по ГК | C15: 1.0590859e+08 | W15: 11 | X15: =(33000*1.05)*2 -> 69300 | Y15: Том 5
B16: Стоимость РД 2 этап по ССРСС | C16: =105864.73*1000 -> 105864730 | W16: 12 | X16: =(31000*1.05*1.2)+(31000*1.05*1.2*0.35)*1 -> 52731 | Y16: Том 5
C17: =C15/C16 -> 1.0004143 | W17: 13 | X17: 69300 | Y17: Том 5
W18: 14 | X18: 52731 | Y18: Том 6
W19: 15 | X19: 52731 | Y19: Том 3
W20: 16 | X20: =(33000*1.05)*2 -> 69300 | Y20: Том 3 | AB20: =SUM(X53,AB11,AF11) -> 3301168 | AC20: =SUM(Y53,AC11,AG11) -> 3301168 | AD20: =AB20-AC20 -> 0.01
W21: 17 | X21: =(14450*1.05) -> 15172.5 | Y21: Том 5
W22: 18 | X22: 15172.5 | Y22: Том 4
W23: 19 | X23: 15172.5 | Y23: Том 7
W24: Всего | X24: =SUM(X5:X23) -> 841812.3
W25: в текущих ценах (кэф = 5,42) | X25: =X24*5.42 -> 4562622.7
W26: в том числе стадия "Р" | X26: =X25*0.6 -> 2737573.6
W27: с кэф пересчета | X27: =ROUND(X26*C10,2) -> 2819021.1
O29: j | W29: общий кэф | X29: =5.42*0.6*C10 -> 3.3487526
W31: Том 1 | X31: =SUM(X5,X12,X11) -> 234603.6
X32: =ROUND(X31*X29,2) -> 785629.42
W34: Том 2 | X34: =SUM(X6,X13) -> 54232.5
X35: =ROUND(X34*X29,2) -> 181611.23
W37: Том 3 | X37: =SUM(X10,X19,X20) -> 138673.5
X38: =ROUND(X37*X29,2) -> 464383.24
W40: Том 4 | X40: =SUM(X22) -> 15172.5
X41: =ROUND(X40*X29,2) -> 50808.95
W43: Том 5 | X43: =SUM(X7,X8,X14,X15,X16,X17,X21) -> 312919.95
X44: =ROUND(X43*X29,2) -> 1047891.5
W46: Том 6 | X46: =SUM(X9,X18) -> 71037.75
X47: =ROUND(X46*X29,2) -> 237887.85
W49: Том 7 | X49: =SUM(X23) -> 15172.5
X50: =ROUND(X49*X29,2) -> 50808.95
...

Sheet Приложение к служебной записке
A1: Пересчет стоимости рабочей документации (стадия Р) по объекту «Организация пассажирского сообщения от станции Москва — Октябрьская — Пассажирская до проектируемого ТПУ «Завидово» через остановочный пункт Путепроводная Октябрьской железной дороги». 1 Этап
B3: После экспертизы стоимость контракта была скорректирована под выделенные лимиты бюджетных обязательств. Для этого использовался общий (комбинированный) коэффициент, который учитывает и инфляцию (индекс-дефлятор), и понижение цены до уровня финансирования. Так как этот коэффициент в документах напрямую не указан, он был выведен математически: сметная стоимость была разделена на итоговую цену государственного контракта (ГК).
B4: Комбинированный индекс К = | C4: Сметная стоимость / Стоимость по ГК
B5: 3 205 790,21 / 3 301 168,00 = 1,02975172539441
G6: =Лист1!C4/D32 -> 1.0297517
A7: № п/п | B7: Шифр комплекта РД | C7: Наименование комплекта РД | D7: Стоимость по Сметам без учета дефлятора | E7: Стоимость по сметам с учетом дефлятора | F7: Стоимость по ведомости подрядчика, руб. (без НДС) | G7: Отклонение, руб.
A8: 1 | B8: 2 | C8: 3 | D8: 4 | F8: 5 | G8: 6
B9: Переустройство сетей связи
A10: 1 | B10: 002-ПСД/2026-НСС-1 | C10: Переустройство кабелей связи ПАО "Ростелеком", ПАО "Вымпелком" на ПК111+17 | D10: =ROUND(Лист1!X31*5.42*0.6,2) -> 762930.91 | E10: =ROUND(D10*$G$6,2) -> 785629.42 | F10: 785628 | G10: =F10-E10 -> -1.42
A11: 2 | B11: 002-ПСД/2026-НСС-2 | C11: Переустройство кабелей связи ПАО "Ростелеком, ПАО "Вымпелком" на ПК111+17 | D11: =ROUND(Лист1!X34*5.42*0.6,2) -> 176364.09 | E11: =ROUND(D11*$G$6,2) -> 181611.23 | F11: 181610 | G11: =F11-E11 -> -1.23
A12: 3 | B12: 002-ПСД/2026-НСС-3 | C12: Переустройство кабелей связи АО "Воентелеком" на ПК 59+78,95 | D12: =ROUND(Лист1!X37*5.42*0.6,2) -> 450966.22 | E12: =ROUND(D12*$G$6,2) -> 464383.24 | F12: 464382 | G12: =F12-E12 -> -1.24
A13: 4 | B13: 002-ПСД/2026-НСС-4 | C13: Защита кабелей связи ПАО "МТС" на ПК 58+35,44. | D13: =ROUND(Лист1!X40*5.42*0.6,2) -> 49340.97 | E13: =ROUND(D13*$G$6,2) -> 50808.95 | F13: 50805 | G13: =F13-E13 -> -3.95
A14: 5 | B14: 002-ПСД/2026-НСС-5 | C14: Переустройство и защита кабелей связи ООО "Связьсервис" на ПК 58+08,67 на ПК 59+00,00 | D14: =ROUND(Лист1!X43*5.42*0.6,2) -> 1017615.7 | E14: =ROUND(D14*$G$6,2) -> 1047891.5 | F14: 1047890 | G14: =F14-E14 -> -1.5
A15: 6 | B15: 002-ПСД/2026-НСС-6 | C15: Переустройство и защита кабелей связи ООО "Связьсервис" на ПК 108+85,90 | D15: =ROUND(Лист1!X46*5.42*0.6,2) -> 231014.76 | E15: =ROUND(D15*$G$6,2) -> 237887.85 | F15: 237887 | G15: =F15-E15 -> -0.85
A16: 7 | B16: 002-ПСД/2026-НСС-7 | C16: Переустройство кабеля связи "Речьсвязьинформ" на ПК59+10,04 | D16: =ROUND(Лист1!X49*5.42*0.6,2) -> 49340.97 | E16: =ROUND(D16*$G$6,2) -> 50808.95 | F16: 50806 | G16: =F16-E16 -> -2.95
B17: Итого по переустройству сетей связи | D17: =SUM(D10:D16) -> 2737573.6 | E17: =SUM(E10:E16) -> 2819021.1 | F17: =SUM(F10:F16) -> 2819008 | G17: =F17-E17 -> -13.14
B18: Переустройство линии электроснабжения
A19: 8 | B19: 002-ПСД/2026-ЭС-1 | C19: Переустройство сетей наружного освещения на ПК 110+90.82. | D19: Определить данный параметр не представляется возможным, поскольку в сметных расчетах отсутствует привязка к пикетажу | E19: Определить данный параметр не представляется возможным, поскольку в сметных расчетах отсутствует привязка к пикетажу | F19: 7139 | G19: Определить данный параметр не представляется возможным, поскольку в сметных расчетах отсутствует привязка к пикетажу
A20: 9 | B20: 002-ПСД/2026-ЭС-1 | C20: Переустройство КЛ-10кВ №18 ПС Мошково на ПК116+91,41 | F20: 36350
A21: 10 | B21: 002-ПСД/2026-ЭС-2 | C21: Переустройство ВЛ-10кВ №18 ПС Энергетик на ПК108+12,74 | F21: 53332
A22: 11 | B22: 002-ПСД/2026-ЭС-3 | C22: Переустройство ВЛ-10кВ на ПК110+58,12 | F22: 37920
A23: 12 | B23: 002-ПСД/2026-ЭС-4 | C23: Переустройство ВЛ-10кВ на ПК100+35,9 | F23: 45579
A24: 13 | B24: 002-ПСД/2026-ЭС-5 | C24: Переустройство ВЛ-10кВ на ПК87+94,24 | F24: 47447
A25: 14 | B25: 002-ПСД/2026-ЭС-6 | C25: Переустройство ВЛ-10кВ на ПК78+75,6 | F25: 44376
B26: Итого по переустройству линий электроснабжения | D26: =ROUND(Лист1!AB10,2) -> 264280.28 | E26: =ROUND(D26*G6,2) -> 272143.07 | F26: =SUM(F19:F25) -> 272143 | G26: =F26-E26 -> -0.07
B27: Переустройство (обустройство) сетей газоснабжения
A28: 15 | B28: 1-3-СГТ-Э1-ТКР3-1 | C28: Наружные газопроводы d325 | D28: =ROUND(Лист1!AF5*(339.92/62.72)*0.6,2) -> 128807.3 | E28: =ROUND(D28*G6,2) -> 132639.54 | F28: 132654 | G28: =F28-E28 -> 14.46
A29: 16 | B29: № 75-П-2026 | C29: Наружные газопроводы d108 | D29: =ROUND(Лист1!AF6*(339.92/62.72)*0.6,2) -> 75129.03 | E29: =ROUND(D29*G6,2) -> 77364.25 | F29: 77363 | G29: =F29-E29 -> -1.25
B30: Итого по переустройству сетей газоснабжения | D30: =SUM(D28:D29) -> 203936.33 | E30: =SUM(E28:E29) -> 210003.79 | F30: =SUM(F28:F29) -> 210017 | G30: =F30-E30 -> 13.21
D32: =SUM(D17,D26,D30) -> 3205790.2 | E32: =SUM(E17,E26,E30) -> 3301168 | F32: =SUM(F17,F26,F30) -> 3301168 | G32: =SUM(G17,G26,G30) -> -1.4551915e-10
