Workbook

Sheet RV_DATA
A1: BuildingFinished | B1: Trud | C1: Mash | D1: Mat | E1: MatZak | F1: Oborud | G1: OborudZak | H1: ZeroStoim | I1: NegativeKoll | J1: ReUnionKollResurcy | K1: UnionOneUchRes | L1: IdLevel | M1: ViewCodes | N1: UnionCodes | O1: PEREVOZKA
A2: 1 | B2: 1 | C2: 1 | D2: 1 | E2: 1 | F2: 1 | G2: 1 | H2: 0 | I2: 1 | J2: 0 | K2: 1 | L2: 38182922 | M2: 0 | N2: 0 | O2: 0
A4: TYPE | B4: SOURCE_LINK | C4: RABMAT_EX | D4: TIP_RAB | E4: TYPE_TRUD | F4: TAB | G4: NAME | H4: EDIZM | I4: KOLL | J4: UCH | K4: PRICE_B | L4: PRICE_ED | M4: STOIM_B | N4: PRICE_C | O4: STOIM_C | P4: ZPM_B | Q4: ZPM_ED | R4: STOIM_ZPM_B | S4: ZPM_C | T4: STOIM_ZPM_C | U4: RABMAT | V4: WBS | W4: CBSI | X4: CBSII | Y4: TechSpecCVORPP | Z4: CRC_GR_RES | AA4: CRC_B | AB4: CRC_C
A6: =Source!A20 -> 3 | B6: 20 | G6: =Source!G20 -> ремонт трубы
A7: 20 | B7: 3 | C7: 2 | D7: 0 | E7: =SmtRes!AV3 -> 1 | F7: =SmtRes!I3 -> 91.01.05-084 | G7: =SmtRes!K3 -> Экскаваторы одноковшовые дизельные на гусеничном ходу, объем ковша 0,4 м3 | H7: =SmtRes!O3 -> маш.-ч | I7: =SmtRes!Y3*Source!I24 -> 1.32255 | J7: =SmtRes!AO3 -> 0 | K7: =SmtRes!AF3 -> 947.64 | M7: =ROUND(I7*K7, 2) -> 1253.3 | N7: =SmtRes!AB3 -> 1250.88 | O7: =SmtRes!DG3 -> 1654.35 | P7: =SmtRes!AG3 -> 497.4 | R7: =ROUND(I7*P7, 2) -> 657.84 | S7: =SmtRes!AC3 -> 497.4 | T7: =SmtRes!DH3 -> 657.84 | U7: 2 | Z7: =SmtRes!X3 -> 1473885390 | AA7: 1567848987 | AB7: 1216713234
A8: 20 | B8: 1 | C8: 1 | D8: 0 | E8: =SmtRes!AV1 -> 1 | F8: =SmtRes!I1 -> 1-100-20 | G8: =SmtRes!K1 -> Средний разряд работы 2,0 | H8: =SmtRes!O1 -> чел.-ч. | I8: =SmtRes!Y1*Source!I24 -> 0.2655 | J8: =SmtRes!AO1 -> 0 | K8: =SmtRes!AH1 -> 352.06 | M8: =ROUND(I8*K8, 2) -> 93.47 | N8: =SmtRes!AD1 -> 352.06 | O8: =SmtRes!DI1 -> 93.47 | P8: =SmtRes!AG1 -> 0 | R8: =ROUND(I8*P8, 2) -> 0 | S8: =SmtRes!AC1 -> 0 | T8: =SmtRes!DH1 -> 0 | U8: 1 | Z8: =SmtRes!X1 -> 370475345 | AA8: 1406990596 | AB8: 1406990596
A9: 20 | B9: 7 | C9: 2 | D9: 0 | E9: =SmtRes!AV7 -> 1 | F9: =SmtRes!I7 -> 91.14.02-001 | G9: =SmtRes!K7 -> Автомобили бортовые, грузоподъемность до 5 т | H9: =SmtRes!O7 -> маш.-ч | I9: =SmtRes!Y7*Source!I25 -> 0.0384 | J9: =SmtRes!AO7 -> 0 | K9: =SmtRes!AF7 -> 652.84 | M9: =ROUND(I9*K9, 2) -> 25.07 | N9: =SmtRes!AB7 -> 652.84 | O9: =SmtRes!DG7 -> 25.07 | P9: =SmtRes!AG7 -> 432.81 | R9: =ROUND(I9*P9, 2) -> 16.62 | S9: =SmtRes!AC7 -> 432.81 | T9: =SmtRes!DH7 -> 16.62 | U9: 2 | Z9: =SmtRes!X7 -> -849950259 | AA9: 106755230 | AB9: 106755230
A10: 20 | B10: 6 | C10: 2 | D10: 0 | E10: =SmtRes!AV6 -> 1 | F10: =SmtRes!I6 -> 91.10.05-009 | G10: =SmtRes!K6 -> Трубоукладчики, номинальная грузоподъемность 35 т | H10: =SmtRes!O6 -> маш.-ч | I10: =SmtRes!Y6*Source!I25 -> 0.992 | J10: =SmtRes!AO6 -> 0 | K10: =SmtRes!AF6 -> 4403.56 | M10: =ROUND(I10*K10, 2) -> 4368.33 | N10: =SmtRes!AB6 -> 4931.99 | O10: =SmtRes!DG6 -> 4892.53 | P10: =SmtRes!AG6 -> 707.35 | R10: =ROUND(I10*P10, 2) -> 701.69 | S10: =SmtRes!AC6 -> 707.35 | T10: =SmtRes!DH6 -> 701.69 | U10: 2 | Z10: =SmtRes!X6 -> -1505731505 | AA10: 1516374314 | AB10: 929036850
A11: 20 | B11: 4 | C11: 1 | D11: 0 | E11: =SmtRes!AV4 -> 1 | F11: =SmtRes!I4 -> 1-100-40 | G11: =SmtRes!K4 -> Средний разряд работы 4,0 | H11: =SmtRes!O4 -> чел.-ч. | I11: =SmtRes!Y4*Source!I25 -> 15.008 | J11: =SmtRes!AO4 -> 0 | K11: =SmtRes!AH4 -> 432.81 | M11: =ROUND(I11*K11, 2) -> 6495.61 | N11: =SmtRes!AD4 -> 432.81 | O11: =SmtRes!DI4 -> 6495.61 | P11: =SmtRes!AG4 -> 0 | R11: =ROUND(I11*P11, 2) -> 0 | S11: =SmtRes!AC4 -> 0 | T11: =SmtRes!DH4 -> 0 | U11: 1 | Z11: =SmtRes!X4 -> 888410196 | AA11: 795807998 | AB11: 795807998
A12: 20 | B12: 20 | C12: 3 | D12: 0 | E12: =SmtRes!AV20 -> 0 | F12: =SmtRes!I20 -> 11.1.03.01-0067 | G12: =SmtRes!K20 -> Брус обрезной хвойных пород (ель, сосна), естественной влажности, длина 2-6,5 м, ширина 100 и более мм, толщина 100 и более мм, сорт III | H12: =SmtRes!O20 -> м3 | I12: =SmtRes!Y20*Source!I27 -> 0.027 | J12: =SmtRes!AO20 -> 0 | K12: =SmtRes!AE20 -> 16655 | M12: =ROUND(I12*K12, 2) -> 449.69 | N12: =SmtRes!AA20 -> 13324 | O12: =SmtRes!DF20 -> 359.75 | P12: =SmtRes!AG20 -> 0 | R12: =ROUND(I12*P12, 2) -> 0 | S12: =SmtRes!AC20 -> 0 | T12: =SmtRes!DH20 -> 0 | U12: 3 | Z12: =SmtRes!X20 -> -831399682 | AA12: -1480605263 | AB12: -1360243399
A13: 20 | B13: 19 | C13: 3 | D13: 0 | E13: =SmtRes!AV19 -> 0 | F13: =SmtRes!I19 -> 01.3.02.09-0022 | G13: =SmtRes!K19 -> Пропан-бутан смесь техническая | H13: =SmtRes!O19 -> кг | I13: =SmtRes!Y19*Source!I27 -> 4.0656 | J13: =SmtRes!AO19 -> 0 | K13: =SmtRes!AE19 -> 41.38 | M13: =ROUND(I13*K13, 2) -> 168.23 | N13: =SmtRes!AA19 -> 57.1 | O13: =SmtRes!DF19 -> 232.15 | P13: =SmtRes!AG19 -> 0 | R13: =ROUND(I13*P13, 2) -> 0 | S13: =SmtRes!AC19 -> 0 | T13: =SmtRes!DH19 -> 0 | U13: 3 | Z13: =SmtRes!X19 -> -1568219933 | AA13: 1588463070 | AB13: 766106269
A14: 20 | B14: 18 | C14: 3 | D14: 0 | E14: =SmtRes!AV18 -> 0 | F14: =SmtRes!I18 -> 01.3.02.08-0001 | G14: =SmtRes!K18 -> Кислород газообразный технический | H14: =SmtRes!O18 -> м3 | I14: =SmtRes!Y18*Source!I27 -> 1.59 | J14: =SmtRes!AO18 -> 0 | K14: =SmtRes!AE18 -> 89 | M14: =ROUND(I14*K14, 2) -> 141.51 | N14: =SmtRes!AA18 -> 89 | O14: =SmtRes!DF18 -> 141.51 | P14: =SmtRes!AG18 -> 0 | R14: =ROUND(I14*P14, 2) -> 0 | S14: =SmtRes!AC18 -> 0 | T14: =SmtRes!DH18 -> 0 | U14: 3 | Z14: =SmtRes!X18 -> -2058989610 | AA14: 1504361348 | AB14: 1504361348
A15: 20 | B15: 17 | C15: 2 | D15: 0 | E15: =SmtRes!AV17 -> 1 | F15: =SmtRes!I17 -> 91.17.04-042 | G15: =SmtRes!K17 -> Аппараты для газовой сварки и резки | H15: =SmtRes!O17 -> маш.-ч | I15: =SmtRes!Y17*Source!I27 -> 0.44 | J15: =SmtRes!AO17 -> 0 | K15: =SmtRes!AF17 -> 4.35 | M15: =ROUND(I15*K15, 2) -> 1.91 | N15: =SmtRes!AB17 -> 5.35 | O15: =SmtRes!DG17 -> 2.35 | P15: =SmtRes!AG17 -> 0 | R15: =ROUND(I15*P15, 2) -> 0 | S15: =SmtRes!AC17 -> 0 | T15: =SmtRes!DH17 -> 0 | U15: 2 | Z15: =SmtRes!X17 -> -880363394 | AA15: 1145571634 | AB15: -51089833
A16: 20 | B16: 16 | C16: 2 | D16: 0 | E16: =SmtRes!AV16 -> 1 | F16: =SmtRes!I16 -> 91.10.05-009 | G16: =SmtRes!K16 -> Трубоукладчики, номинальная грузоподъемность 35 т | H16: =SmtRes!O16 -> маш.-ч | I16: =SmtRes!Y16*Source!I27 -> 0.75 | J16: =SmtRes!AO16 -> 0 | K16: =SmtRes!AF16 -> 4403.56 | M16: =ROUND(I16*K16, 2) -> 3302.67 | N16: =SmtRes!AB16 -> 4931.99 | O16: =SmtRes!DG16 -> 3698.99 | P16: =SmtRes!AG16 -> 707.35 | R16: =ROUND(I16*P16, 2) -> 530.51 | S16: =SmtRes!AC16 -> 707.35 | T16: =SmtRes!DH16 -> 530.51 | U16: 2 | Z16: =SmtRes!X16 -> -1505731505 | AA16: 1516374314 | AB16: 929036850
A17: 20 | B17: 14 | C17: 1 | D17: 0 | E17: =SmtRes!AV14 -> 1 | F17: =SmtRes!I14 -> 1-100-47 | G17: =SmtRes!K14 -> Средний разряд работы 4,7 | H17: =SmtRes!O14 -> чел.-ч. | I17: =SmtRes!Y14*Source!I27 -> 1.59 | J17: =SmtRes!AO14 -> 0 | K17: =SmtRes!AH14 -> 478.03 | M17: =ROUND(I17*K17, 2) -> 760.07 | N17: =SmtRes!AD14 -> 478.03 | O17: =SmtRes!DI14 -> 760.07 | P17: =SmtRes!AG14 -> 0 | R17: =ROUND(I17*P17, 2) -> 0 | S17: =SmtRes!AC14 -> 0 | T17: =SmtRes!DH14 -> 0 | U17: 1 | Z17: =SmtRes!X14 -> 1521243167 | AA17: -1434346882 | AB17: -1434346882
A18: 20 | B18: 29 | C18: 3 | D18: 0 | E18: =SmtRes!AV29 -> 0 | F18: =SmtRes!I29 -> 04.3.01.09-0014 | G18: =SmtRes!K29 -> Раствор готовый кладочный, цементный, М100 | H18: =SmtRes!O29 -> м3 | I18: =SmtRes!Y29*Source!I28 -> 0.066 | J18: =SmtRes!AO29 -> 0 | K18: =SmtRes!AE29 -> 5769.31 | M18: =ROUND(I18*K18, 2) -> 380.77 | N18: =SmtRes!AA29 -> 5769.31 | O18: =SmtRes!DF29 -> 380.77 | P18: =SmtRes!AG29 -> 0 | R18: =ROUND(I18*P18, 2) -> 0 | S18: =SmtRes!AC29 -> 0 | T18: =SmtRes!DH29 -> 0 | U18: 3 | Z18: =SmtRes!X29 -> -2089581116 | AA18: 1543752563 | AB18: 1543752563
A19: 20 | B19: 28 | C19: 3 | D19: 0 | E19: =SmtRes!AV28 -> 0 | F19: =SmtRes!I28 -> 03.2.01.01-0001 | G19: =SmtRes!K28 -> Портландцемент бездобавочный общестроительный ЦЕМ 0 32,5Н | H19: =SmtRes!O28 -> т | I19: =SmtRes!Y28*Source!I28 -> 0.02656 | J19: =SmtRes!AO28 -> 0 | K19: =SmtRes!AE28 -> 4800.85 | M19: =ROUND(I19*K19, 2) -> 127.51 | N19: =SmtRes!AA28 -> 9073.61 | O19: =SmtRes!DF28 -> 241 | P19: =SmtRes!AG28 -> 0 | R19: =ROUND(I19*P19, 2) -> 0 | S19: =SmtRes!AC28 -> 0 | T19: =SmtRes!DH28 -> 0 | U19: 3 | Z19: =SmtRes!X28 -> 269049756 | AA19: 580301888 | AB19: -1771451004
A20: 20 | B20: 27 | C20: 3 | D20: 0 | E20: =SmtRes!AV27 -> 0 | F20: =SmtRes!I27 -> 01.7.07.29-0322 | G20: =SmtRes!K27 -> Канат пропитанный (каболка) из льняного и джутового волокна, канализационный и водопроводный, отжатый, диаметр 10-100 мм | H20: =SmtRes!O27 -> кг | I20: =SmtRes!Y27*Source!I28 -> 8.4 | J20: =SmtRes!AO27 -> 0 | K20: =SmtRes!AE27 -> 152.78 | M20: =ROUND(I20*K20, 2) -> 1283.35 | N20: =SmtRes!AA27 -> 207.78 | O20: =SmtRes!DF27 -> 1745.35 | P20: =SmtRes!AG27 -> 0 | R20: =ROUND(I20*P20, 2) -> 0 | S20: =SmtRes!AC27 -> 0 | T20: =SmtRes!DH27 -> 0 | U20: 3 | Z20: =SmtRes!X27 -> 219322737 | AA20: 269364198 | AB20: 1772365322
A21: 20 | B21: 26 | C21: 3 | D21: 0 | E21: =SmtRes!AV26 -> 0 | F21: =SmtRes!I26 -> 01.7.03.01-0001 | G21: =SmtRes!K26 -> Вода | H21: =SmtRes!O26 -> м3 | I21: =SmtRes!Y26*Source!I28 -> 7.85 | J21: =SmtRes!AO26 -> 0 | K21: =SmtRes!AE26 -> 35.71 | M21: =ROUND(I21*K21, 2) -> 280.32 | N21: =SmtRes!AA26 -> 26.07 | O21: =SmtRes!DF26 -> 204.65 | P21: =SmtRes!AG26 -> 0 | R21: =ROUND(I21*P21, 2) -> 0 | S21: =SmtRes!AC26 -> 0 | T21: =SmtRes!DH26 -> 0 | U21: 3 | Z21: =SmtRes!X26 -> 1964556667 | AA21: 1781038258 | AB21: -471873250
A22: 20 | B22: 25 | C22: 3 | D22: 0 | E22: =SmtRes!AV25 -> 0 | F22: =SmtRes!I25 -> 01.1.02.10-1022 | G22: =SmtRes!K25 -> Хризотил (асбест хризотиловый), группа 6К, марки 6К-45, 6К-30, 6К-20, 6К-5 | H22: =SmtRes!O25 -> т | I22: =SmtRes!Y25*Source!I28 -> 0.0114 | J22: =SmtRes!AO25 -> 0 | K22: =SmtRes!AE25 -> 21588.35 | M22: =ROUND(I22*K22, 2) -> 246.11 | N22: =SmtRes!AA25 -> 25474.25 | O22: =SmtRes!DF25 -> 290.41 | P22: =SmtRes!AG25 -> 0 | R22: =ROUND(I22*P22, 2) -> 0 | S22: =SmtRes!AC25 -> 0 | T22: =SmtRes!DH25 -> 0 | U22: 3 | Z22: =SmtRes!X25 -> 192185020 | AA22: 728816804 | AB22: -973196742
A23: 20 | B23: 24 | C23: 2 | D23: 0 | E23: =SmtRes!AV24 -> 1 | F23: =SmtRes!I24 -> 91.14.02-001 | G23: =SmtRes!K24 -> Автомобили бортовые, грузоподъемность до 5 т | H23: =SmtRes!O24 -> маш.-ч | I23: =SmtRes!Y24*Source!I28 -> 0.048 | J23: =SmtRes!AO24 -> 0 | K23: =SmtRes!AF24 -> 652.84 | M23: =ROUND(I23*K23, 2) -> 31.34 | N23: =SmtRes!AB24 -> 652.84 | O23: =SmtRes!DG24 -> 31.34 | P23: =SmtRes!AG24 -> 432.81 | R23: =ROUND(I23*P23, 2) -> 20.77 | S23: =SmtRes!AC24 -> 432.81 | T23: =SmtRes!DH24 -> 20.77 | U23: 2 | Z23: =SmtRes!X24 -> -849950259 | AA23: 106755230 | AB23: 106755230
A24: 20 | B24: 23 | C24: 2 | D24: 0 | E24: =SmtRes!AV23 -> 1 | F24: =SmtRes!I23 -> 91.10.05-009 | G24: =SmtRes!K23 -> Трубоукладчики, номинальная грузоподъемность 35 т | H24: =SmtRes!O23 -> маш.-ч | I24: =SmtRes!Y23*Source!I28 -> 1.24 | J24: =SmtRes!AO23 -> 0 | K24: =SmtRes!AF23 -> 4403.56 | M24: =ROUND(I24*K24, 2) -> 5460.41 | N24: =SmtRes!AB23 -> 4931.99 | O24: =SmtRes!DG23 -> 6115.67 | P24: =SmtRes!AG23 -> 707.35 | R24: =ROUND(I24*P24, 2) -> 877.11 | S24: =SmtRes!AC23 -> 707.35 | T24: =SmtRes!DH23 -> 877.11 | U24: 2 | Z24: =SmtRes!X23 -> -1505731505 | AA24: 1516374314 | AB24: 929036850
A25: 20 | B25: 21 | C25: 1 | D25: 0 | E25: =SmtRes!AV21 -> 1 | F25: =SmtRes!I21 -> 1-100-40 | G25: =SmtRes!K21 -> Средний разряд работы 4,0 | H25: =SmtRes!O21 -> чел.-ч. | I25: =SmtRes!Y21*Source!I28 -> 18.76 | J25: =SmtRes!AO21 -> 0 | K25: =SmtRes!AH21 -> 432.81 | M25: =ROUND(I25*K25, 2) -> 8119.52 | N25: =SmtRes!AD21 -> 432.81 | O25: =SmtRes!DI21 -> 8119.52 | P25: =SmtRes!AG21 -> 0 | R25: =ROUND(I25*P25, 2) -> 0 | S25: =SmtRes!AC21 -> 0 | T25: =SmtRes!DH21 -> 0 | U25: 1 | Z25: =SmtRes!X21 -> 888410196 | AA25: 795807998 | AB25: 795807998
A26: 20 | B26: 32 | C26: 2 | D26: 0 | E26: =SmtRes!AV32 -> 1 | F26: =SmtRes!I32 -> 91.01.01-046 | G26: =SmtRes!K32 -> Бульдозеры, мощность 303 кВт (410 л.с.) | H26: =SmtRes!O32 -> маш.-ч | I26: =SmtRes!Y32*Source!I30 -> 0.09 | J26: =SmtRes!AO32 -> 0 | K26: =SmtRes!AF32 -> 5605.48 | M26: =ROUND(I26*K26, 2) -> 504.49 | N26: =SmtRes!AB32 -> 5605.48 | O26: =SmtRes!DG32 -> 504.49 | P26: =SmtRes!AG32 -> 707.35 | R26: =ROUND(I26*P26, 2) -> 63.66 | S26: =SmtRes!AC32 -> 707.35 | T26: =SmtRes!DH32 -> 63.66 | U26: 2 | Z26: =SmtRes!X32 -> 626856282 | AA26: -1281970117 | AB26: -1281970117
A27: =Source!A31 -> 18 | B27: 31 | C27: 2 | D27: =Source!BI31 -> 1 | E27: =Source!FS31 -> 1 | F27: =Source!F31 -> 91.01.05-104 | G27: =Source!G31 -> Экскаваторы одноковшовые дизельные на пневмоколесном ходу, объем ковша 0,4 м3 | H27: =Source!H31 -> маш.-ч | I27: =Source!I31 -> 0.09 | J27: 1 | K27: =Source!AD31 -> 1162.81 | M27: =ROUND(K27*I27, 2) -> 104.65 | N27: =Source!CQ31 -> 0 | O27: =ROUND(N27*I27, 2) -> 0 | P27: =Source!AE31 -> 497.4 | R27: =ROUND(P27*I27, 2) -> 44.77 | S27: =Source!AE31*IF(Source!BS31<> 0, Source!BS31, 1) -> 497.4 | T27: =ROUND(S27*I27, 2) -> 44.77 | U27: 2 | Z27: =Source!GF31 -> -598721075 | AA27: -1992513835 | AB27: -1937554257
A28: =Source!A32 -> 17 | B28: 32 | C28: 2 | D28: =Source!BI32 -> 1 | E28: =Source!FS32 -> 1 | F28: =Source!F32 -> 91.01.01-046 | G28: =Source!G32 -> Бульдозеры, мощность 303 кВт (410 л.с.) | H28: =Source!H32 -> маш.-ч | I28: =Source!I32 -> -0.09 | J28: 1 | K28: =Source!AD32 -> 5605.48 | M28: =ROUND(K28*I28, 2) -> -504.49 | N28: =Source!CQ32 -> 0 | O28: =ROUND(N28*I28, 2) -> 0 | P28: =Source!AE32 -> 707.35 | R28: =ROUND(P28*I28, 2) -> -63.66 | S28: =Source!AE32*IF(Source!BS32<> 0, Source!BS32, 1) -> 707.35 | T28: =ROUND(S28*I28, 2) -> -63.66 | U28: 2 | Z28: =Source!GF32 -> 626856282 | AA28: -1281970117 | AB28: 888318738
A29: 20 | B29: 44 | C29: 3 | D29: 0 | E29: =SmtRes!AV44 -> 0 | F29: =SmtRes!I44 -> 14.1.05.03-0011 | G29: =SmtRes!K44 -> Клей фенолополивинилацетальный, марка БФ-2Н | H29: =SmtRes!O44 -> т | I29: =SmtRes!Y44*Source!I33 -> 1.25e-05 | J29: =SmtRes!AO44 -> 0 | K29: =SmtRes!AE44 -> 442593.68 | M29: =ROUND(I29*K29, 2) -> 5.53 | N29: =SmtRes!AA44 -> 686020.2 | O29: =SmtRes!DF44 -> 8.58 | P29: =SmtRes!AG44 -> 0 | R29: =ROUND(I29*P29, 2) -> 0 | S29: =SmtRes!AC44 -> 0 | T29: =SmtRes!DH44 -> 0 | U29: 3 | Z29: =SmtRes!X44 -> 1435964893 | AA29: 236554803 | AB29: -910808008
A30: 20 | B30: 42 | C30: 3 | D30: 0 | E30: =SmtRes!AV42 -> 0 | F30: =SmtRes!I42 -> 01.7.20.08-0162 | G30: =SmtRes!K42 -> Ткань мешочная, ширина 950 мм, поверхностная плотность 190 г/м2 | H30: =SmtRes!O42 -> 10 м2 | I30: =SmtRes!Y42*Source!I33 -> 0.0001 | J30: =SmtRes!AO42 -> 0 | K30: =SmtRes!AE42 -> 592.04 | M30: =ROUND(I30*K30, 2) -> 0.06 | N30: =SmtRes!AA42 -> 953.18 | O30: =SmtRes!DF42 -> 0.1 | P30: =SmtRes!AG42 -> 0 | R30: =ROUND(I30*P30, 2) -> 0 | S30: =SmtRes!AC42 -> 0 | T30: =SmtRes!DH42 -> 0 | U30: 3 | Z30: =SmtRes!X42 -> -1756344661 | AA30: -1533044596 | AB30: -1094930439
A31: 20 | B31: 41 | C31: 3 | D31: 0 | E31: =SmtRes!AV41 -> 0 | F31: =SmtRes!I41 -> 01.7.20.08-0021 | G31: =SmtRes!K41 -> Брезент с огнеупорной пропиткой | H31: =SmtRes!O41 -> м2 | I31: =SmtRes!Y41*Source!I33 -> 0.0008 | J31: =SmtRes!AO41 -> 0 | K31: =SmtRes!AE41 -> 108.68 | M31: =ROUND(I31*K31, 2) -> 0.09 | N31: =SmtRes!AA41 -> 174.97 | O31: =SmtRes!DF41 -> 0.14 | P31: =SmtRes!AG41 -> 0 | R31: =ROUND(I31*P31, 2) -> 0 | S31: =SmtRes!AC41 -> 0 | T31: =SmtRes!DH41 -> 0 | U31: 3 | Z31: =SmtRes!X41 -> 2050518453 | AA31: -1943925511 | AB31: 1676897807
A32: 20 | B32: 40 | C32: 3 | D32: 0 | E32: =SmtRes!AV40 -> 0 | F32: =SmtRes!I40 -> 01.7.06.03-0002 | G32: =SmtRes!K40 -> Ленты антикоррозионные из ПВХ с липким слоем с одной стороны для изоляции трубопроводов, цвет черный, ширина 450 мм, толщина 0,4 мм | H32: =SmtRes!O40 -> м2 | I32: =SmtRes!Y40*Source!I33 -> 0.478 | J32: =SmtRes!AO40 -> 0 | K32: =SmtRes!AE40 -> 62.74 | M32: =ROUND(I32*K32, 2) -> 29.99 | N32: =SmtRes!AA40 -> 123.6 | O32: =SmtRes!DF40 -> 59.08 | P32: =SmtRes!AG40 -> 0 | R32: =ROUND(I32*P32, 2) -> 0 | S32: =SmtRes!AC40 -> 0 | T32: =SmtRes!DH40 -> 0 | U32: 3 | Z32: =SmtRes!X40 -> 1711398520 | AA32: 1396930422 | AB32: -1323178595
A33: 20 | B33: 39 | C33: 2 | D33: 0 | E33: =SmtRes!AV39 -> 1 | F33: =SmtRes!I39 -> 91.16.01-002 | G33: =SmtRes!K39 -> Электростанции передвижные, мощность 4 кВт | H33: =SmtRes!O39 -> маш.-ч | I33: =SmtRes!Y39*Source!I33 -> 0.00993 | J33: =SmtRes!AO39 -> 0 | K33: =SmtRes!AF39 -> 130.39 | M33: =ROUND(I33*K33, 2) -> 1.29 | N33: =SmtRes!AB39 -> 130.39 | O33: =SmtRes!DG39 -> 1.29 | P33: =SmtRes!AG39 -> 432.81 | R33: =ROUND(I33*P33, 2) -> 4.3 | S33: =SmtRes!AC39 -> 432.81 | T33: =SmtRes!DH39 -> 4.3 | U33: 2 | Z33: =SmtRes!X39 -> -245244677 | AA33: 1669558037 | AB33: 1669558037
A34: 20 | B34: 38 | C34: 2 | D34: 0 | E34: =SmtRes!AV38 -> 1 | F34: =SmtRes!I38 -> 91.14.02-001 | G34: =SmtRes!K38 -> Автомобили бортовые, грузоподъемность до 5 т | H34: =SmtRes!O38 -> маш.-ч | I34: =SmtRes!Y38*Source!I33 -> 0.00106 | J34: =SmtRes!AO38 -> 0 | K34: =SmtRes!AF38 -> 652.84 | M34: =ROUND(I34*K34, 2) -> 0.69 | N34: =SmtRes!AB38 -> 652.84 | O34: =SmtRes!DG38 -> 0.69 | P34: =SmtRes!AG38 -> 432.81 | R34: =ROUND(I34*P34, 2) -> 0.46 | S34: =SmtRes!AC38 -> 432.81 | T34: =SmtRes!DH38 -> 0.46 | U34: 2 | Z34: =SmtRes!X38 -> -849950259 | AA34: 106755230 | AB34: 106755230
A35: 20 | B35: 37 | C35: 2 | D35: 0 | E35: =SmtRes!AV37 -> 1 | F35: =SmtRes!I37 -> 91.10.05-009 | G35: =SmtRes!K37 -> Трубоукладчики, номинальная грузоподъемность 35 т | H35: =SmtRes!O37 -> маш.-ч | I35: =SmtRes!Y37*Source!I33 -> 0.01218 | J35: =SmtRes!AO37 -> 0 | K35: =SmtRes!AF37 -> 4403.56 | M35: =ROUND(I35*K35, 2) -> 53.64 | N35: =SmtRes!AB37 -> 4931.99 | O35: =SmtRes!DG37 -> 60.07 | P35: =SmtRes!AG37 -> 707.35 | R35: =ROUND(I35*P35, 2) -> 8.62 | S35: =SmtRes!AC37 -> 707.35 | T35: =SmtRes!DH37 -> 8.62 | U35: 2 | Z35: =SmtRes!X37 -> -1505731505 | AA35: 1516374314 | AB35: 929036850
A36: 20 | B36: 35 | C36: 1 | D36: 0 | E36: =SmtRes!AV35 -> 1 | F36: =SmtRes!I35 -> 1-100-42 | G36: =SmtRes!K35 -> Средний разряд работы 4,2 | H36: =SmtRes!O35 -> чел.-ч. | I36: =SmtRes!Y35*Source!I33 -> 0.14 | J36: =SmtRes!AO35 -> 0 | K36: =SmtRes!AH35 -> 445.73 | M36: =ROUND(I36*K36, 2) -> 62.4 | N36: =SmtRes!AD35 -> 445.73 | O36: =SmtRes!DI35 -> 62.4 | P36: =SmtRes!AG35 -> 0 | R36: =ROUND(I36*P36, 2) -> 0 | S36: =SmtRes!AC35 -> 0 | T36: =SmtRes!DH35 -> 0 | U36: 1 | Z36: =SmtRes!X35 -> 1522950421 | AA36: 2015934539 | AB36: 2015934539
A37: =Source!A34 -> 18 | B37: 34 | C37: 3 | D37: =Source!BI34 -> 1 | E37: =Source!FS34 -> 0 | F37: =Source!F34 -> 14.4.01.15-1002 | G37: =Source!G34 -> Грунтовка полимерная для повышения адгезии битумно-полимерных мастик и герметиков при герметизации деформационных швов асфальтобетонных и цементобетонных покрытий | H37: =Source!H34 -> т | I37: =Source!I34 -> 0.001 | J37: 1 | K37: =Source!AC34 -> 411791.94 | M37: =ROUND(K37*I37, 2) -> 411.79 | N37: =Source!CQ34 -> 522975.76 | O37: =ROUND(N37*I37, 2) -> 522.98 | P37: =Source!AE34 -> 0 | R37: =ROUND(P37*I37, 2) -> 0 | S37: =Source!AE34*IF(Source!BS34<> 0, Source!BS34, 1) -> 0 | T37: =ROUND(S37*I37, 2) -> 0 | U37: 3 | Z37: =Source!GF34 -> 7353553 | AA37: -248603019 | AB37: 602379180
A38: =Source!A35 -> 18 | B38: 35 | C38: 3 | D38: =Source!BI35 -> 1 | E38: =Source!FS35 -> 0 | F38: =Source!F35 -> 12.1.02.15-0041 | G38: =Source!G35 -> Материал рулонный гидроизоляционный изол, резино-битумный, без полимерных добавок | H38: =Source!H35 -> м2 | I38: =Source!I35 -> 0.85 | J38: 1 | K38: =Source!AC35 -> 126.14 | M38: =ROUND(K38*I38, 2) -> 107.22 | N38: =Source!CQ35 -> 172.81 | O38: =ROUND(N38*I38, 2) -> 146.89 | P38: =Source!AE35 -> 0 | R38: =ROUND(P38*I38, 2) -> 0 | S38: =Source!AE35*IF(Source!BS35<> 0, Source!BS35, 1) -> 0 | T38: =ROUND(S38*I38, 2) -> 0 | U38: 3 | Z38: =Source!GF35 -> -848550540 | AA38: 2142095169 | AB38: -1719168864
A39: 20 | B39: 49 | C39: 2 | D39: 0 | E39: =SmtRes!AV49 -> 1 | F39: =SmtRes!I49 -> 91.18.01-007 | G39: =SmtRes!K49 -> Компрессоры винтовые передвижные с двигателем внутреннего сгорания, давление до 0,7 МПа (7 атм), производительность до 5,4 м3/мин | H39: =SmtRes!O49 -> маш.-ч | I39: =SmtRes!Y49*Source!I36 -> 1.179 | J39: =SmtRes!AO49 -> 0 | K39: =SmtRes!AF49 -> 411.37 | M39: =ROUND(I39*K39, 2) -> 485.01 | N39: =SmtRes!AB49 -> 411.37 | O39: =SmtRes!DG49 -> 485.01 | P39: =SmtRes!AG49 -> 432.81 | R39: =ROUND(I39*P39, 2) -> 510.28 | S39: =SmtRes!AC49 -> 432.81 | T39: =SmtRes!DH49 -> 510.28 | U39: 2 | Z39: =SmtRes!X49 -> 1282244495 | AA39: -919029990 | AB39: -919029990
A40: 20 | B40: 48 | C40: 2 | D40: 0 | E40: =SmtRes!AV48 -> 1 | F40: =SmtRes!I48 -> 91.08.09-023 | G40: =SmtRes!K48 -> Трамбовки пневматические при работе от передвижных компрессорных установок | H40: =SmtRes!O48 -> маш.-ч | I40: =SmtRes!Y48*Source!I36 -> 4.725 | J40: =SmtRes!AO48 -> 0 | K40: =SmtRes!AF48 -> 2.41 | M40: =ROUND(I40*K40, 2) -> 11.39 | N40: =SmtRes!AB48 -> 2.7 | O40: =SmtRes!DG48 -> 12.76 | P40: =SmtRes!AG48 -> 0 | R40: =ROUND(I40*P40, 2) -> 0 | S40: =SmtRes!AC48 -> 0 | T40: =SmtRes!DH48 -> 0 | U40: 2 | Z40: =SmtRes!X48 -> 4789874 | AA40: 201212123 | AB40: -1275274398
A41: 20 | B41: 46 | C41: 1 | D41: 0 | E41: =SmtRes!AV46 -> 1 | F41: =SmtRes!I46 -> 1-100-30 | G41: =SmtRes!K46 -> Средний разряд работы 3,0 | H41: =SmtRes!O46 -> чел.-ч. | I41: =SmtRes!Y46*Source!I36 -> 5.6385 | J41: =SmtRes!AO46 -> 0 | K41: =SmtRes!AH46 -> 384.36 | M41: =ROUND(I41*K41, 2) -> 2167.21 | N41: =SmtRes!AD46 -> 384.36 | O41: =SmtRes!DI46 -> 2167.21 | P41: =SmtRes!AG46 -> 0 | R41: =ROUND(I41*P41, 2) -> 0 | S41: =SmtRes!AC46 -> 0 | T41: =SmtRes!DH46 -> 0 | U41: 1 | Z41: =SmtRes!X46 -> -1833565283 | AA41: -1658114278 | AB41: -1658114278
A42: 20 | B42: 55 | C42: 3 | D42: 0 | E42: =SmtRes!AV55 -> 0 | F42: =SmtRes!I55 -> 02.3.01.02-1104 | G42: =SmtRes!K55 -> Песок природный для строительных работ I класс, средний | H42: =SmtRes!O55 -> м3 | I42: =SmtRes!Y55*Source!I37 -> 57.33 | J42: =SmtRes!AO55 -> 0 | K42: =SmtRes!AE55 -> 757.36 | M42: =ROUND(I42*K42, 2) -> 43419.45 | N42: =SmtRes!AA55 -> 757.36 | O42: =SmtRes!DF55 -> 43419.45 | P42: =SmtRes!AG55 -> 0 | R42: =ROUND(I42*P42, 2) -> 0 | S42: =SmtRes!AC55 -> 0 | T42: =SmtRes!DH55 -> 0 | U42: 3 | Z42: =SmtRes!X55 -> 318135557 | AA42: -1879287007 | AB42: -1879287007
...

Sheet Смета по ФСНБ 421+557прРИМ
A1: =Source!B1 -> Smeta.RU (495) 974-1589
A2: Наименование программного продукта | F2: Программа для ЭВМ «Программа: «Smeta.RU» версия 12»
A4: Наименование редакции сметных нормативов | F4: =IF(Source!CQ12 <> "", Source!CQ12, "") -> Приказ Минстроя России от 30.12.2021 г. № 1046/пр; Приказ Минстроя России от 04.08.2020 г. № 421/пр; Приказ Минстроя России от 21.12.2020 г. № 812/пр; Приказ Минстроя России от 11.12.2020 г. № 774/пр | CO4: =IF(Source!CQ12 <> "", Source!CQ12, "") -> Приказ Минстроя России от 30.12.2021 г. № 1046/пр; Приказ Минстроя России от 04.08.2020 г. № 421/пр; Приказ Минстроя России от 21.12.2020 г. № 812/пр; Приказ Минстроя России от 11.12.2020 г. № 774/пр
A6: Реквизиты приказа Минстроя России об утверждении дополнений и изменений к сметным нормативам | F6: =IF(Source!CV12 <> "", Source!CV12, "") -> Приказ Минстроя России от 18.05.2022 г. № 378/пр; Приказ Минстроя России от 26.08.2022 г. № 703/пр; Приказ Минстроя России от 26.10.2022 г. № 905/пр; Приказ Минстроя России от 27.12.2022 г. № 1133/пр; Приказ Минстроя России от 10.02.2023 г. № 84/пр; Приказ Минстроя России от 11.05.2023 г. № 335/пр; Приказ Минстроя России от 02.08.2023 г. № 551/пр; Приказ Минстроя России от 14.11.2023 г. № 817/пр; Приказ Минстроя России от 16.02.2024 г. № 102/пр; Приказ Минстроя России от 13.05.2024 г. № 323/пр; Приказ Минстроя России от 09.08.2024 г. № 524/пр; Приказ Минстроя России от 07.11.2024 г. № 747/пр; Приказ Минстроя России от 07.02.2025 г. № 69/пр; Приказ Минстроя России от 19.05.2025 г. № 299/пр; Приказ Минстроя России от 14.08.2025 г. № 490/пр; Приказ Минстроя России от 12.11.2025 г. № 696/пр; Приказ Минстроя России от 17.02.2026 г. № 91/пр; Приказ Минстроя России от 07.07.2022 г. № 557/пр; Приказ Минстроя России от 30.01.2024 г. № 55/пр; Приказ Минстроя России от 23.01.2025 г. № 30/пр; Приказ Минстроя России от 02.09.2021 г. № 636/пр; Приказ Минстроя России от 26.07.2022 г. № 611/пр; Приказ Минстроя России от 22.04.2022 г. № 317/пр | CO6: =IF(Source!CV12 <> "", Source!CV12, "") -> Приказ Минстроя России от 18.05.2022 г. № 378/пр; Приказ Минстроя России от 26.08.2022 г. № 703/пр; Приказ Минстроя России от 26.10.2022 г. № 905/пр; Приказ Минстроя России от 27.12.2022 г. № 1133/пр; Приказ Минстроя России от 10.02.2023 г. № 84/пр; Приказ Минстроя России от 11.05.2023 г. № 335/пр; Приказ Минстроя России от 02.08.2023 г. № 551/пр; Приказ Минстроя России от 14.11.2023 г. № 817/пр; Приказ Минстроя России от 16.02.2024 г. № 102/пр; Приказ Минстроя России от 13.05.2024 г. № 323/пр; Приказ Минстроя России от 09.08.2024 г. № 524/пр; Приказ Минстроя России от 07.11.2024 г. № 747/пр; Приказ Минстроя России от 07.02.2025 г. № 69/пр; Приказ Минстроя России от 19.05.2025 г. № 299/пр; Приказ Минстроя России от 14.08.2025 г. № 490/пр; Приказ Минстроя России от 12.11.2025 г. № 696/пр; Приказ Минстроя России от 17.02.2026 г. № 91/пр; Приказ Минстроя России от 07.07.2022 г. № 557/пр; Приказ Минстроя России от 30.01.2024 г. № 55/пр; Приказ Минстроя России от 23.01.2025 г. № 30/пр; Приказ Минстроя России от 02.09.2021 г. № 636/пр; Приказ Минстроя России от 26.07.2022 г. № 611/пр; Приказ Минстроя России от 22.04.2022 г. № 317/пр
A8: Реквизиты письма Минстроя России об индексах изменения сметной стоимости строительства, включаемые в федеральный реестр сметных нормативов и размещаемые в федеральной государственной информационной системе ценообразования в строительстве, подготовленного в соответствии с пунктом 85 Методики расчета индексов изменения сметной стоимости строительства, утвержденной приказом Министерства строительства и жилищно-коммунального хозяйства Российской Федерации от 5 июня 2019 г. N 326/пр | F8: Письмо Минстроя России от 25.02.2026 № 9859-ИФ/09
A10: Реквизиты нормативного правового акта об утверждении оплаты труда, утверждаемый в соответствии с пунктом 22(1) Правилами мониторинга цен, утвержденными постановлением Правительства Российской Федерации от 23 декабря 2016 г. N 1452 | F10: Постановление Правительства Тверской области от 25.04.2025 г. № 229-пп
A12: Обоснование принятых текущих цен на строительные ресурсы | F12: ФГИС ЦС, конъюнктурный анализ
A14: Наименование субъекта Российской Федерации | F14: =IF(Source!CZ12 <> "", Source!CZ12, "")
A16: Наименование зоны субъекта Российской Федерации | F16: =IF(Source!DA12 <> "", Source!DA12, "")
A19: ремонт трубы
A20: (наименование стройки)
A22: =IF(Source!G12<>"Новый объект", Source!G12, "") -> ремонт трубы
A23: (наименование объекта капитального строительства)
A25: =CONCATENATE( "ЛОКАЛЬНАЯ СМЕТА № ", Source!L20, " ",Source!CM20) -> ЛОКАЛЬНАЯ СМЕТА № Новая локальная смета
A27: =IF(Source!G20<>"Новая локальная смета", Source!G20, "") -> ремонт трубы
A28: (наименование работ и затрат)
A31: Составлен | C31: Ресурсно-индексным | D31: методом
A33: Основание
C34: (проектная и (или) иная техническая документация)
A36: Составлен(а) в текущем уровне цен на I квартал 2026 года
A38: Сметная стоимость | C38: =C41+C42+C43+C44 -> 110.67 | E38: тыс. руб.
G39: Средства на оплату труда рабочих | K39: =ROUND(SUM(AR52:AR316)/1000, 2) -> 20.92 | L39: тыс. руб.
B40: в том числе: | G40: Средства на оплату труда машинистов | K40: =ROUND(SUM(AT52:AT316)/1000, 2) -> 7.26 | L40: тыс. руб.
B41: строительных работ | C41: =ROUND((Source!F59)/1000, 2) -> 110.67 | E41: тыс. руб. | G41: Нормативные затраты труда рабочих | K41: =Source!F64 -> 49.772 | L41: чел.-ч.
B42: монтажных работ | C42: =ROUND((Source!F60)/1000, 2) -> 0 | E42: тыс. руб. | G42: Нормативные затраты труда машинистов | K42: =Source!F65 -> 12.61312 | L42: чел.-ч.
B43: оборудования | C43: =ROUND((Source!F51)/1000, 2) -> 0 | E43: тыс. руб.
B44: прочих затрат | C44: =ROUND((Source!F61)/1000, 2) -> 0 | E44: тыс. руб.
A46: № п/п | B46: Обоснование | C46: Наименование работ и затрат | D46: Единица измерения | E46: Количество | H46: Сметная стоимость, руб.
E50: на единицу измерения | F50: коэффициенты | G50: всего с учетом коэффициентов | H50: на единицу измерения в базисном уровне цен | I50: индекс | J50: на единицу измерения в текущем уровне цен | K50: коэффициенты | L50: всего в текущем уровне цен
A51: 1 | B51: 2 | C51: 3 | D51: 4 | E51: 5 | F51: 6 | G51: 7 | H51: 8 | I51: 9 | J51: 10 | K51: 11 | L51: 12
A52: 1 | B52: ГЭСН 01-01-010-38 | C52: =Source!G24 -> Разработка грунта в отвал экскаваторами, вместимость ковша 0,4 (0,3-0,45) м3, группа грунтов: 2 | D52: =Source!H24 -> 1000 м3 | E52: =Source!K24 -> 0.045 | G52: =Source!I24 -> 0.045
C53: ="Объем: "&Source!I24&"=45/"&"1000" -> Объем: 0,045=45/1000
B54: 1 | C54: ОТ (ЗТ) | D54: чел.-ч. | G54: =Source!U24 -> 0.2655 | L54: =SUM(L55:L55)-SUMIF(CE55:CE55, 1, L55:L55) -> 93.47
B55: 1-100-20 | C55: Средний разряд работы 2,0 | D55: чел.-ч. | E55: 5.9 | G55: =SmtRes!CX1 -> 0.2655 | J55: =SmtRes!CZ1 -> 352.06 | L55: =SmtRes!DI1 -> 93.47
B56: 2 | C56: ЭМ | L56: =SUM(L57:L59)-SUMIF(CE57:CE59, 1, L57:L59) -> 1654.35
C57: ОТм(ЗТм) | D57: чел.-ч. | G57: =Source!V24 -> 1.32255 | L57: =SUMIF(CE58:CE59, 1, L58:L59) -> 657.84 | CE57: 1
B58: 91.01.05-084 | C58: Экскаваторы одноковшовые дизельные на гусеничном ходу, объем ковша 0,4 м3 | D58: маш.-ч | E58: 29.39 | G58: =SmtRes!CX3 -> 1.32255 | H58: =SmtRes!CZ3 -> 947.64 | I58: =SmtRes!AJ3 -> 1.32 | J58: =ROUND(H58*I58, 2) -> 1250.88 | L58: =SmtRes!DG3 -> 1654.35
B59: 4-100-050 | C59: ОТм(ЗТм) Средний разряд машинистов 5 | D59: чел.-ч. | E59: =SmtRes!DO3*SmtRes!AT3 -> 29.39 | G59: =ROUND(E59*G52, 7) -> 1.32255 | J59: =ROUND(SmtRes!AG3/SmtRes!DO3, 2) -> 497.4 | L59: =SmtRes!DH3 -> 657.84 | CE59: 1
C60: Итого прямые затраты | L60: =L54+L56+L57 -> 2405.66
C61: ФОТ | L61: =SUM(AR52:AR64)+SUM(AS52:AS64)+SUM(AT52:AT64)+SUM(AU52:AU64)+SUM(AV52:AV64) -> 751.31
...

Sheet Source
A1: 0 | B1: Smeta.RU (495) 974-1589 | D1: _PS_ | F1: 0 | G1: 0 | H1: 0 | I1: Smeta.RU | K1: 1 | L1: 28227 | M1: 38175928 | N1: 12 | O1: 1 | P1: 0 | Q1: 5
A4: 8 | B4: 1 | C4: -1 | F4: Новый проект 4 | G4: ремонт трубы | EC4: 0
A12: 1 | B12: 134 | C12: 0 | D12: =ROW(A77) -> 77 | E12: 0 | F12: Новый объект строительства | G12: ремонт трубы | I12: 0 | K12: 0 | L12: 0 | M12: 523 | O12: 0 | P12: 0 | Q12: 7 | R12: 0 | T12: 4 | V12: 0 | BB12: 0 | BH12: Сметные нормы списания | BI12: Коды ценников | BJ12: 1 | BK12: 1 | BL12: 0 | BM12: 1 | BN12: 1 | BO12: 0 | BP12: 6 | BQ12: 2 | BR12: 1 | BS12: 1 | BT12: 0 | BU12: 0 | BV12: 1 | BW12: 0 | BX12: 0 | BY12: ФСНБ-2022_И17 | BZ12: Версия 1.17.0 для ФСНБ-2022 И17 | CA12: ФСНБ-2022 - Изменения И17 | CB12: ФСНБ-2022 - Изменения И17 | CC12: ФСНБ-2022 - Изменения И17 | CD12: ФСНБ-2022 - Изменения И17 | CE12: Поправки для ФСНБ-2022 от 25.02.2026 г И17 (55/пр) Капитальный ремонт производственных зданий | CF12: 0 | CG12: 0 | CH12: 487489544 | CK12: 18 | CQ12: Приказ Минстроя России от 30.12.2021 г. № 1046/пр; Приказ Минстроя России от 04.08.2020 г. № 421/пр; Приказ Минстроя России от 21.12.2020 г. № 812/пр; Приказ Минстроя России от 11.12.2020 г. № 774/пр | CR12: ГСН | CS12: 46073 | CT12: 540 | CU12: 17 | CV12: Приказ Минстроя России от 18.05.2022 г. № 378/пр; Приказ Минстроя России от 26.08.2022 г. № 703/пр; Приказ Минстроя России от 26.10.2022 г. № 905/пр; Приказ Минстроя России от 27.12.2022 г. № 1133/пр; Приказ Минстроя России от 10.02.2023 г. № 84/пр; Приказ Минстроя России от 11.05.2023 г. № 335/пр; Приказ Минстроя России от 02.08.2023 г. № 551/пр; Приказ Минстроя России от 14.11.2023 г. № 817/пр; Приказ Минстроя России от 16.02.2024 г. № 102/пр; Приказ Минстроя России от 13.05.2024 г. № 323/пр; Приказ Минстроя России от 09.08.2024 г. № 524/пр; Приказ Минстроя России от 07.11.2024 г. № 747/пр; Приказ Минстроя России от 07.02.2025 г. № 69/пр; Приказ Минстроя России от 19.05.2025 г. № 299/пр; Приказ Минстроя России от 14.08.2025 г. № 490/пр; Приказ Минстроя России от 12.11.2025 г. № 696/пр; Приказ Минстроя России от 17.02.2026 г. № 91/пр; Приказ Минстроя России от 07.07.2022 г. № 557/пр; Приказ Минстроя России от 30.01.2024 г. № 55/пр; Приказ Минстроя России от 23.01.2025 г. № 30/пр; Приказ Минстроя России от 02.09.2021 г. № 636/пр; Приказ Минстроя России от 26.07.2022 г. № 611/пр; Приказ Минстроя России от 22.04.2022 г. № 317/пр | CY12: 0 | EC12: 0
A15: 15 | B15: 1
A18: 52 | B18: =B77 -> 134 | C18: =C77 -> 1 | D18: =D77 -> 12 | E18: =E77 -> 0 | F18: =F77 -> Новый объект строительства | G18: =G77 -> ремонт трубы | O18: =O77 -> 52656.07 | P18: =P77 -> 4333.36 | Q18: =Q77 -> 22333.26 | R18: =R77 -> 5074.08 | S18: =S77 -> 20915.37 | T18: =T77 -> 0 | U18: =U77 -> 49.772 | V18: =V77 -> 12.61312 | ... GX18: =GX77 -> 0
A20: 3 | B20: 1 | D20: =ROW(A42) -> 42 | F20: Новая локальная смета | G20: ремонт трубы | I20: 0 | K20: 0 | L20: Новая локальная смета | S20: 0 | V20: 0 | BX20: 0 | CF20: 0 | CG20: 0
A22: 52 | B22: =B42 -> 1 | C22: =C42 -> 3 | D22: =D42 -> 20 | E22: =E42 -> 0 | F22: =F42 -> Новая локальная смета | G22: =G42 -> ремонт трубы | O22: =O42 -> 52656.07 | P22: =P42 -> 4333.36 | Q22: =Q42 -> 22333.26 | R22: =R42 -> 5074.08 | S22: =S42 -> 20915.37 | T22: =T42 -> 0 | U22: =U42 -> 49.772 | V22: =V42 -> 12.61312 | ... GX22: =GX42 -> 0
A24: 17 | B24: 1 | C24: =ROW(SmtRes!A3) -> 3 | D24: =ROW(EtalonRes!A3) -> 3 | E24: 1 | F24: 01-01-010-38 | G24: Разработка грунта в отвал экскаваторами, вместимость ковша 0,4 (0,3-0,45) м3, группа грунтов: 2 | H24: 1000 м3 | I24: =ROUND(ROUND(45/1000,5),7) -> 0.045 | J24: 0 | K24: =ROUND(ROUND(45/1000,5),7) -> 0.045 | O24: =ROUND(CP24,2) -> 2405.66 | P24: =SUMIF(SmtRes!AQ1:'SmtRes'!AQ3,"=1",SmtRes!DF1:'SmtRes'!DF3) -> 0 | Q24: =SUMIF(SmtRes!AQ1:'SmtRes'!AQ3,"=1",SmtRes!DG1:'SmtRes'!DG3) -> 1654.35 | R24: =SUMIF(SmtRes!AQ1:'SmtRes'!AQ3,"=1",SmtRes!DH1:'SmtRes'!DH3) -> 657.84 | S24: =SUMIF(SmtRes!AQ1:'SmtRes'!AQ3,"=1",SmtRes!DI1:'SmtRes'!DI3) -> 93.47 | T24: =ROUND(CU24*I24,2) -> 0 | U24: =SUMIF(SmtRes!AQ1:'SmtRes'!AQ3,"=1",SmtRes!CV1:'SmtRes'!CV3) -> 0.2655 | V24: =SUMIF(SmtRes!AQ1:'SmtRes'!AQ3,"=1",SmtRes!CW1:'SmtRes'!CW3) -> 1.32255 | W24: =ROUND(CX24*I24,2) -> 0 | X24: =ROUND(CY24,2) -> 691.21 | Y24: =ROUND(CZ24,2) -> 345.6 | AA24: 38182922 | AB24: =ROUND((AC24+AD24+AF24),6) -> 29928.294 | AC24: =ROUND((0),6) -> 0 | AD24: =ROUND((((SUM(SmtRes!BR1:'SmtRes'!BR3))-(SUM(SmtRes!BS1:'SmtRes'!BS3)))+AE24),6) -> 27851.14 | AE24: =ROUND((SUM(SmtRes!BS1:'SmtRes'!BS3)),6) -> 14618.586 | AF24: =ROUND((SUM(SmtRes!BT1:'SmtRes'!BT3)),6) -> 2077.154 | AG24: =ROUND((AP24),6) -> 0 | AH24: =(SUM(SmtRes!BU1:'SmtRes'!BU3)) -> 5.9 | AI24: =(SUM(SmtRes!BV1:'SmtRes'!BV3)) -> 29.39 | AJ24: =(AS24) -> 0 | AK24: 44546.88 | AL24: 0 | AM24: 27851.14 | AN24: 14618.586 | AO24: 2077.154 | AP24: 0 | AQ24: 5.9 | AR24: 29.39 | AS24: 0 | AT24: 92 | AU24: 46 | AV24: 1 | AW24: 1 | AZ24: 1 | BA24: 1 | BB24: 1 | BC24: 1 | BH24: 0 | BI24: 1 | BJ24: ГЭСН-2022, 01-01-010-38, приказ Минстроя России от 18.05.2022 г. № 378/пр | BM24: 1001 | BN24: 0 | BP24: 0 | BQ24: 2 | BR24: 0 | BS24: 1 | BT24: 1 | BU24: 1 | BV24: 1 | BW24: 1 | BX24: 1 | BZ24: 92 | CA24: 46 | CE24: 0 | CF24: 0 | CG24: 0 | CM24: 0 | CO24: 0 | CP24: =(P24+Q24+S24+R24) -> 2405.66 | CQ24: =SUMIF(SmtRes!AQ1:'SmtRes'!AQ3,"=1",SmtRes!AA1:'SmtRes'!AA3) -> 0 | CR24: =SUMIF(SmtRes!AQ1:'SmtRes'!AQ3,"=1",SmtRes!AB1:'SmtRes'!AB3) -> 1250.88 | CS24: =SUMIF(SmtRes!AQ1:'SmtRes'!AQ3,"=1",SmtRes!AC1:'SmtRes'!AC3) -> 497.4 | CT24: =SUMIF(SmtRes!AQ1:'SmtRes'!AQ3,"=1",SmtRes!AD1:'SmtRes'!AD3) -> 352.06 | CU24: =AG24 -> 0 | CV24: =SUMIF(SmtRes!AQ1:'SmtRes'!AQ3,"=1",SmtRes!BU1:'SmtRes'!BU3) -> 5.9 | CW24: =SUMIF(SmtRes!AQ1:'SmtRes'!AQ3,"=1",SmtRes!BV1:'SmtRes'!BV3) -> 29.39 | CX24: =AJ24 -> 0 | CY24: =(((S24+R24)*AT24)/100) -> 691.2052 | CZ24: =(((S24+R24)*AU24)/100) -> 345.6026 | DN24: 0 | DO24: 0 | DP24: 1 | DQ24: 1 | DU24: 1007 | DV24: 1000 м3 | DW24: 1000 м3 | DX24: 1000 | EE24: 35227734 | EF24: 2 | EG24: Общестроительные работы | EH24: 1 | EI24: Земляные работы | EJ24: 1 | EK24: 1001 | EL24: Земляные работы, выполняемые: механизированным способом | EM24: ФЕР-01 | EQ24: 0 | ER24: 0 | ES24: 0 | ET24: 0 | EU24: 0 | EV24: 0 | EW24: 5.9 | EX24: 29.39 | EY24: 0 | FQ24: 0 | FR24: 0 | FS24: 0 | FX24: 92 | FY24: 46 | GD24: 1 | GF24: 329302311 | GG24: 2 | GH24: 1 | GI24: -2 | GJ24: 0 | GK24: 0 | GL24: =ROUND(IF(AND(BH24=3,BI24=3,FS24<>0),P24,0),2) -> 0 | GM24: =ROUND(O24+X24+Y24,2)+GX24 -> 3442.47 | GN24: =IF(OR(BI24=0,BI24=1),GM24-GX24,0) -> 3442.47 | GO24: =IF(BI24=2,GM24-GX24,0) -> 0 | GP24: =IF(BI24=4,GM24-GX24,0) -> 0 | GR24: 0 | GS24: 3 | GT24: 0 | GV24: =ROUND((GT24),6) -> 0 | GW24: 1 | GX24: =ROUND(HC24*I24,2) -> 0 | HA24: 0 | HB24: 0 | HC24: =GV24*GW24 -> 0 | HN24: Пр/812-001.1-1 | HO24: Пр/774-001.1 | HP24: Земляные работы, выполняемые: механизированным способом | HQ24: Земляные работы, выполняемые: механизированным способом | HS24: 0 | IK24: 0
A25: 17 | B25: 1 | C25: =ROW(SmtRes!A13) -> 13 | D25: =ROW(EtalonRes!A13) -> 13 | E25: 2 | F25: 23-01-007-05 | G25: Демонтаж - Укладка трубопроводов из железобетонных безнапорных раструбных труб диаметром: 1000 мм | H25: 100 м | I25: =ROUND(ROUND(10/100,5),7) -> 0.1 | J25: 0 | K25: =ROUND(ROUND(10/100,5),7) -> 0.1 | O25: =ROUND(CP25,2) -> 12131.52 | P25: =SUMIF(SmtRes!AQ4:'SmtRes'!AQ13,"=1",SmtRes!DF4:'SmtRes'!DF13) -> 0 | Q25: =SUMIF(SmtRes!AQ4:'SmtRes'!AQ13,"=1",SmtRes!DG4:'SmtRes'!DG13) -> 4917.6 | R25: =SUMIF(SmtRes!AQ4:'SmtRes'!AQ13,"=1",SmtRes!DH4:'SmtRes'!DH13) -> 718.31 | S25: =SUMIF(SmtRes!AQ4:'SmtRes'!AQ13,"=1",SmtRes!DI4:'SmtRes'!DI13) -> 6495.61 | T25: =ROUND(CU25*I25,2) -> 0 | U25: =SUMIF(SmtRes!AQ4:'SmtRes'!AQ13,"=1",SmtRes!CV4:'SmtRes'!CV13) -> 15.008 | V25: =SUMIF(SmtRes!AQ4:'SmtRes'!AQ13,"=1",SmtRes!CW4:'SmtRes'!CW13) -> 1.0304 | W25: =ROUND(CX25*I25,2) -> 0 | X25: =ROUND(CY25,2) -> 8440.29 | Y25: =ROUND(CZ25,2) -> 5338.3 | AA25: 38182922 | AB25: =ROUND((AC25+AD25+AF25),6) -> 108890.13 | AC25: =ROUND((0),6) -> 0 | AD25: =ROUND((((SUM(SmtRes!BR4:'SmtRes'!BR13))-(SUM(SmtRes!BS4:'SmtRes'!BS13)))+AE25),6) -> 43934.006 | AE25: =ROUND((SUM(SmtRes!BS4:'SmtRes'!BS13)),6) -> 7183.111 | AF25: =ROUND((SUM(SmtRes!BT4:'SmtRes'!BT13)),6) -> 64956.125 | AG25: =ROUND((AP25),6) -> 0 | AH25: =(SUM(SmtRes!BU4:'SmtRes'!BU13)) -> 150.08 | AI25: =(SUM(SmtRes!BV4:'SmtRes'!BV13)) -> 10.304 | AJ25: =(AS25) -> 0 | AK25: 168272.23 | AL25: 23180.677 | AM25: 54917.507 | AN25: 8978.8888 | AO25: 81195.156 | AP25: 0 | AQ25: 187.6 | AR25: 12.88 | AS25: 0 | AT25: 117 | AU25: 74 | AV25: 1 | AW25: 1 | AZ25: 1 | BA25: 1 | BB25: 1 | BC25: 1 | BH25: 0 | BI25: 1 | BJ25: ГЭСН-2022 доп.16, 23-01-007-05, приказ Минстроя России от 12.11.2025 г. № 696/пр | BM25: 23001 | BN25: 0 | BP25: 0 | BQ25: 2 | BR25: 0 | BS25: 1 | BT25: 1 | BU25: 1 | BV25: 1 | BW25: 1 | BX25: 1 | BZ25: 117 | CA25: 74 | CE25: 0 | CF25: 0 | CG25: 0 | CM25: 0 | CN25: демонтаж_x000D_ Поправка: 571/пр_2022_п.83_т.2_стр.1_стб.3 Наименование: Разборка и (или) демонтаж строительных конструкций, систем и сетей инженерно-технического обеспечения, в том числе их элементов: сборных бетонных и железобетонных строительных конструкций | CO25: 0 | CP25: =(P25+Q25+S25+R25) -> 12131.52 | CQ25: =SUMIF(SmtRes!AQ4:'SmtRes'!AQ13,"=1",SmtRes!AA4:'SmtRes'!AA13) -> 40551.02 | CR25: =SUMIF(SmtRes!AQ4:'SmtRes'!AQ13,"=1",SmtRes!AB4:'SmtRes'!AB13) -> 5584.83 | CS25: =SUMIF(SmtRes!AQ4:'SmtRes'!AQ13,"=1",SmtRes!AC4:'SmtRes'!AC13) -> 1140.16 | CT25: =SUMIF(SmtRes!AQ4:'SmtRes'!AQ13,"=1",SmtRes!AD4:'SmtRes'!AD13) -> 432.81 | CU25: =AG25 -> 0 | CV25: =SUMIF(SmtRes!AQ4:'SmtRes'!AQ13,"=1",SmtRes!BU4:'SmtRes'!BU13) -> 150.08 | CW25: =SUMIF(SmtRes!AQ4:'SmtRes'!AQ13,"=1",SmtRes!BV4:'SmtRes'!BV13) -> 10.304 | CX25: =AJ25 -> 0 | CY25: =(((S25+R25)*AT25)/100) -> 8440.2864 | CZ25: =(((S25+R25)*AU25)/100) -> 5338.3008 | DB25: 1 | DD25: *0 | DE25: *0,8 | DF25: *0,8 | DG25: *0,8 | DI25: *0,8 | DJ25: *0,8 | DN25: 0 | DO25: 0 | DP25: 1 | DQ25: 1 | DU25: 1003 | DV25: 100 м | DW25: 100 м | DX25: 100 | EE25: 35227794 | EF25: 2 | EG25: Общестроительные работы | EH25: 18 | EI25: Наружные сети водопровода, канализации, теплоснабжения, газопроводы | EJ25: 1 | EK25: 23001 | EL25: Наружные сети водопровода, канализации, теплоснабжения, газопроводы | EM25: ФЕР-23 | EO25: демонтаж_x000D_ Поправка: 571/пр_2022_п.83_т.2_стр.1_стб.3 | EQ25: 0 | ER25: 0 | ES25: 0 | ET25: 0 | EU25: 0 | EV25: 0 | EW25: 187.6 | EX25: 12.88 | EY25: 0 | FQ25: 0 | FR25: 0 | FS25: 0 | FX25: 117 | FY25: 74 | GD25: 1 | GF25: 751095627 | GG25: 2 | GH25: 1 | GI25: -2 | GJ25: 0 | GK25: 0 | GL25: =ROUND(IF(AND(BH25=3,BI25=3,FS25<>0),P25,0),2) -> 0 | GM25: =ROUND(O25+X25+Y25,2)+GX25 -> 25910.11 | GN25: =IF(OR(BI25=0,BI25=1),GM25-GX25,0) -> 25910.11 | GO25: =IF(BI25=2,GM25-GX25,0) -> 0 | GP25: =IF(BI25=4,GM25-GX25,0) -> 0 | GR25: 0 | GS25: 3 | GT25: 0 | GV25: =ROUND((GT25),6) -> 0 | GW25: 1 | GX25: =ROUND(HC25*I25,2) -> 0 | HA25: 0 | HB25: 0 | HC25: =GV25*GW25 -> 0 | HN25: Пр/812-018.0-1 | HO25: Пр/774-018.0 | HP25: Наружные сети водопровода, канализации, теплоснабжения, газопроводы | HQ25: Наружные сети водопровода, канализации, теплоснабжения, газопроводы | HS25: 0 | IK25: 0
A26: 18 | B26: 1 | C26: 13 | E26: 2,1 | F26: 05.1.02.08 | G26: Трубы железобетонные безнапорные раструбные | H26: м | I26: =I25*J26 -> 0 | J26: 0 | K26: 99.7 | O26: =ROUND(CP26,2) -> 0 | P26: =ROUND(CQ26*I26,2) -> 0 | Q26: =ROUND(CR26*I26,2) -> 0 | R26: =ROUND(CS26*I26,2) -> 0 | S26: =ROUND(CT26*I26,2) -> 0 | T26: =ROUND(CU26*I26,2) -> 0 | U26: =ROUND(CV26*I26,7) -> 0 | V26: =ROUND(CW26*I26,7) -> 0 | W26: =ROUND(CX26*I26,2) -> 0 | X26: =ROUND(CY26,2) -> 0 | Y26: =ROUND(CZ26,2) -> 0 | AA26: 38182922 | AB26: =ROUND((AC26+AD26+AF26),6) -> 0 | AC26: =ROUND((ES26),6) -> 0 | AD26: =ROUND((((ET26)-(EU26))+AE26),6) -> 0 | AE26: =ROUND((EU26),6) -> 0 | AF26: =ROUND((EV26),6) -> 0 | AG26: =ROUND((AP26),6) -> 0 | AH26: =(EW26) -> 0 | AI26: =(EX26) -> 0 | AJ26: =(AS26) -> 0 | AK26: 0 | AL26: 0 | AM26: 0 | AN26: 0 | AO26: 0 | AP26: 0 | AQ26: 0 | AR26: 0 | AS26: 0 | AT26: 117 | AU26: 74 | AV26: 1 | AW26: 1 | AZ26: 1 | BA26: 1 | BB26: 1 | BC26: 1 | BH26: 3 | BI26: 1 | BM26: 23001 | BN26: 0 | BP26: 0 | BQ26: 2 | BR26: 0 | BS26: 1 | BT26: 1 | BU26: 1 | BV26: 1 | BW26: 1 | BX26: 1 | BZ26: 117 | CA26: 74 | CE26: 0 | CF26: 0 | CG26: 0 | CM26: 0 | CN26: Поправка: 571/пр_2022_п.83_т.2_стр.1_стб.3_x000D_ Наименование: Разборка и (или) демонтаж строительных конструкций, систем и сетей инженерно-технического обеспечения, в том числе их элементов: сборных бетонных и железобетонных строительных конструкций | CO26: 0 | CP26: =(P26+Q26+S26+R26) -> 0 | CQ26: =ROUND(AL26*BC26,2) -> 0 | CR26: =ROUND(AM26*BB26,2) -> 0 | CS26: =ROUND(AN26*BS26,2) -> 0 | CT26: =ROUND(AO26*BA26,2) -> 0 | CU26: =AG26 -> 0 | CV26: =AH26 -> 0 | CW26: =AI26 -> 0 | CX26: =AJ26 -> 0 | CY26: =(((S26+R26)*AT26)/100) -> 0 | CZ26: =(((S26+R26)*AU26)/100) -> 0 | DN26: 0 | DO26: 0 | DP26: 1 | DQ26: 1 | DU26: 1003 | DV26: м | DW26: м | DX26: 1 | EE26: 35227794 | EF26: 2 | EG26: Общестроительные работы | EH26: 18 | EI26: Наружные сети водопровода, канализации, теплоснабжения, газопроводы | EJ26: 1 | EK26: 23001 | EL26: Наружные сети водопровода, канализации, теплоснабжения, газопроводы | EM26: ФЕР-23 | EO26: Поправка: 571/пр_2022_п.83_т.2_стр.1_стб.3 | EQ26: 0 | ER26: 0 | ES26: 0 | ET26: 0 | EU26: 0 | EV26: 0 | EW26: 0 | EX26: 0 | FQ26: 0 | FR26: 0 | FS26: 0 | FX26: 117 | FY26: 74 | GD26: 1 | GF26: 1219364707 | GG26: 2 | GH26: 1 | GI26: -2 | GJ26: 0 | GK26: 0 | GL26: =ROUND(IF(AND(BH26=3,BI26=3,FS26<>0),P26,0),2) -> 0 | GM26: =ROUND(O26+X26+Y26,2)+GX26 -> 0 | GN26: =IF(OR(BI26=0,BI26=1),GM26-GX26,0) -> 0 | GO26: =IF(BI26=2,GM26-GX26,0) -> 0 | GP26: =IF(BI26=4,GM26-GX26,0) -> 0 | GR26: 0 | GS26: 3 | GT26: 0 | GV26: =ROUND((GT26),6) -> 0 | GW26: 1 | GX26: =ROUND(HC26*I26,2) -> 0 | HA26: 0 | HB26: 0 | HC26: =GV26*GW26 -> 0 | HM26: *0 | HN26: Пр/812-018.0-1 | HO26: Пр/774-018.0 | HP26: Наружные сети водопровода, канализации, теплоснабжения, газопроводы | HQ26: Наружные сети водопровода, канализации, теплоснабжения, газопроводы | HS26: 0 | IK26: 0
A27: 17 | B27: 1 | C27: =ROW(SmtRes!A20) -> 20 | D27: =ROW(EtalonRes!A20) -> 20 | E27: 3 | F27: 25-02-085-05 | G27: Резка на бровке траншеи демонтируемых труб условным диаметром: 1000 мм | H27: РЕЗ | I27: =ROUND(ROUND(1,5),7) -> 1 | J27: 0 | K27: =ROUND(ROUND(1,5),7) -> 1 | O27: =ROUND(CP27,2) -> 5725.33 | P27: =SUMIF(SmtRes!AQ14:'SmtRes'!AQ20,"=1",SmtRes!DF14:'SmtRes'!DF20) -> 733.41 | Q27: =SUMIF(SmtRes!AQ14:'SmtRes'!AQ20,"=1",SmtRes!DG14:'SmtRes'!DG20) -> 3701.34 | R27: =SUMIF(SmtRes!AQ14:'SmtRes'!AQ20,"=1",SmtRes!DH14:'SmtRes'!DH20) -> 530.51 | S27: =SUMIF(SmtRes!AQ14:'SmtRes'!AQ20,"=1",SmtRes!DI14:'SmtRes'!DI20) -> 760.07 | T27: =ROUND(CU27*I27,2) -> 0 | U27: =SUMIF(SmtRes!AQ14:'SmtRes'!AQ20,"=1",SmtRes!CV14:'SmtRes'!CV20) -> 1.59 | V27: =SUMIF(SmtRes!AQ14:'SmtRes'!AQ20,"=1",SmtRes!CW14:'SmtRes'!CW20) -> 0.75 | W27: =ROUND(CX27*I27,2) -> 0 | X27: =ROUND(CY27,2) -> 1432.54 | Y27: =ROUND(CZ27,2) -> 774.35 | AA27: 38182922 | AB27: =ROUND((AC27+AD27+AF27),6) -> 4824.0812 | AC27: =ROUND((SUM(SmtRes!BQ14:'SmtRes'!BQ20)),6) -> 759.42953 | AD27: =ROUND((((SUM(SmtRes!BR14:'SmtRes'!BR20))-(SUM(SmtRes!BS14:'SmtRes'!BS20)))+AE27),6) -> 3304.584 | AE27: =ROUND((SUM(SmtRes!BS14:'SmtRes'!BS20)),6) -> 530.5125 | AF27: =ROUND((SUM(SmtRes!BT14:'SmtRes'!BT20)),6) -> 760.0677 | AG27: =ROUND((AP27),6) -> 0 | AH27: =(SUM(SmtRes!BU14:'SmtRes'!BU20)) -> 1.59 | AI27: =(SUM(SmtRes!BV14:'SmtRes'!BV20)) -> 0.75 | AJ27: =(AS27) -> 0 | AK27: 5354.5937 | AL27: 759.42953 | AM27: 3304.584 | AN27: 530.5125 | AO27: 760.0677 | AP27: 0 | AQ27: 1.59 | AR27: 0.75 | AS27: 0 | AT27: 111 | AU27: 60 | AV27: 1 | AW27: 1 | AZ27: 1 | BA27: 1 | BB27: 1 | BC27: 1 | BH27: 0 | BI27: 1 | BJ27: ГЭСН-2022, 25-02-085-05, приказ Минстроя России от 18.05.2022 г. № 378/пр | BM27: 25001 | BN27: 0 | BP27: 0 | BQ27: 2 | BR27: 0 | BS27: 1 | BT27: 1 | BU27: 1 | BV27: 1 | BW27: 1 | BX27: 1 | BZ27: 111 | CA27: 60 | CE27: 0 | CF27: 0 | CG27: 0 | CM27: 0 | CO27: 0 | CP27: =(P27+Q27+S27+R27) -> 5725.33 | CQ27: =SUMIF(SmtRes!AQ14:'SmtRes'!AQ20,"=1",SmtRes!AA14:'SmtRes'!AA20) -> 13470.1 | CR27: =SUMIF(SmtRes!AQ14:'SmtRes'!AQ20,"=1",SmtRes!AB14:'SmtRes'!AB20) -> 4937.34 | CS27: =SUMIF(SmtRes!AQ14:'SmtRes'!AQ20,"=1",SmtRes!AC14:'SmtRes'!AC20) -> 707.35 | CT27: =SUMIF(SmtRes!AQ14:'SmtRes'!AQ20,"=1",SmtRes!AD14:'SmtRes'!AD20) -> 478.03 | CU27: =AG27 -> 0 | CV27: =SUMIF(SmtRes!AQ14:'SmtRes'!AQ20,"=1",SmtRes!BU14:'SmtRes'!BU20) -> 1.59 | CW27: =SUMIF(SmtRes!AQ14:'SmtRes'!AQ20,"=1",SmtRes!BV14:'SmtRes'!BV20) -> 0.75 | CX27: =AJ27 -> 0 | CY27: =(((S27+R27)*AT27)/100) -> 1432.5438 | CZ27: =(((S27+R27)*AU27)/100) -> 774.348 | DN27: 0 | DO27: 0 | DP27: 1 | DQ27: 1 | DU27: 1013 | DV27: РЕЗ | DW27: РЕЗ | DX27: 1 | EE27: 35227796 | EF27: 2 | EG27: Общестроительные работы | EH27: 19 | EI27: Магистральные и промысловые трубопроводы | EJ27: 1 | EK27: 25001 | EL27: Магистаральные и промысловые водопроводы | EM27: ФЕР-25 | EQ27: 0 | ER27: 0 | ES27: 0 | ET27: 0 | EU27: 0 | EV27: 0 | EW27: 1.59 | EX27: 0.75 | EY27: 0 | FQ27: 0 | FR27: 0 | FS27: 0 | FX27: 111 | FY27: 60 | GD27: 1 | GF27: 1586047166 | GG27: 2 | GH27: 1 | GI27: -2 | GJ27: 0 | GK27: 0 | GL27: =ROUND(IF(AND(BH27=3,BI27=3,FS27<>0),P27,0),2) -> 0 | GM27: =ROUND(O27+X27+Y27,2)+GX27 -> 7932.22 | GN27: =IF(OR(BI27=0,BI27=1),GM27-GX27,0) -> 7932.22 | GO27: =IF(BI27=2,GM27-GX27,0) -> 0 | GP27: =IF(BI27=4,GM27-GX27,0) -> 0 | GR27: 0 | GS27: 3 | GT27: 0 | GV27: =ROUND((GT27),6) -> 0 | GW27: 1 | GX27: =ROUND(HC27*I27,2) -> 0 | HA27: 0 | HB27: 0 | HC27: =GV27*GW27 -> 0 | HN27: Пр/812-019.0-1 | HO27: Пр/774-019.0 | HP27: Магистральные и промысловые трубопроводы | HQ27: Магистральные и промысловые трубопроводы | HS27: 0 | IK27: 0
A28: 17 | B28: 1 | C28: =ROW(SmtRes!A30) -> 30 | D28: =ROW(EtalonRes!A30) -> 30 | E28: 4 | F28: 23-01-007-05 | G28: Укладка трубопроводов из железобетонных безнапорных раструбных труб диаметром: 1000 мм | H28: 100 м | I28: =ROUND(ROUND(10/100,5),7) -> 0.1 | J28: 0 | K28: =ROUND(ROUND(10/100,5),7) -> 0.1 | O28: =ROUND(CP28,2) -> 18026.59 | P28: =SUMIF(SmtRes!AQ21:'SmtRes'!AQ30,"=1",SmtRes!DF21:'SmtRes'!DF30) -> 2862.18 | Q28: =SUMIF(SmtRes!AQ21:'SmtRes'!AQ30,"=1",SmtRes!DG21:'SmtRes'!DG30) -> 6147.01 | R28: =SUMIF(SmtRes!AQ21:'SmtRes'!AQ30,"=1",SmtRes!DH21:'SmtRes'!DH30) -> 897.88 | S28: =SUMIF(SmtRes!AQ21:'SmtRes'!AQ30,"=1",SmtRes!DI21:'SmtRes'!DI30) -> 8119.52 | T28: =ROUND(CU28*I28,2) -> 0 | U28: =SUMIF(SmtRes!AQ21:'SmtRes'!AQ30,"=1",SmtRes!CV21:'SmtRes'!CV30) -> 18.76 | V28: =SUMIF(SmtRes!AQ21:'SmtRes'!AQ30,"=1",SmtRes!CW21:'SmtRes'!CW30) -> 1.288 | W28: =ROUND(CX28*I28,2) -> 0 | X28: =ROUND(CY28,2) -> 10550.36 | Y28: =ROUND(CZ28,2) -> 6672.88 | AA28: 38182922 | AB28: =ROUND((AC28+AD28+AF28),6) -> 159293.34 | AC28: =ROUND((SUM(SmtRes!BQ21:'SmtRes'!BQ30)),6) -> 23180.677 | AD28: =ROUND((((SUM(SmtRes!BR21:'SmtRes'!BR30))-(SUM(SmtRes!BS21:'SmtRes'!BS30)))+AE28),6) -> 54917.507 | AE28: =ROUND((SUM(SmtRes!BS21:'SmtRes'!BS30)),6) -> 8978.8888 | AF28: =ROUND((SUM(SmtRes!BT21:'SmtRes'!BT30)),6) -> 81195.156 | AG28: =ROUND((AP28),6) -> 0 | AH28: =(SUM(SmtRes!BU21:'SmtRes'!BU30)) -> 187.6 | AI28: =(SUM(SmtRes!BV21:'SmtRes'!BV30)) -> 12.88 | AJ28: =(AS28) -> 0 | AK28: 168272.23 | AL28: 23180.677 | AM28: 54917.507 | AN28: 8978.8888 | AO28: 81195.156 | AP28: 0 | AQ28: 187.6 | AR28: 12.88 | AS28: 0 | AT28: 117 | AU28: 74 | AV28: 1 | AW28: 1 | AZ28: 1 | BA28: 1 | BB28: 1 | BC28: 1 | BH28: 0 | BI28: 1 | BJ28: ГЭСН-2022 доп.16, 23-01-007-05, приказ Минстроя России от 12.11.2025 г. № 696/пр | BM28: 23001 | BN28: 0 | BP28: 0 | BQ28: 2 | BR28: 0 | BS28: 1 | BT28: 1 | BU28: 1 | BV28: 1 | BW28: 1 | BX28: 1 | BZ28: 117 | CA28: 74 | CE28: 0 | CF28: 0 | CG28: 0 | CM28: 0 | CO28: 0 | CP28: =(P28+Q28+S28+R28) -> 18026.59 | CQ28: =SUMIF(SmtRes!AQ21:'SmtRes'!AQ30,"=1",SmtRes!AA21:'SmtRes'!AA30) -> 40551.02 | CR28: =SUMIF(SmtRes!AQ21:'SmtRes'!AQ30,"=1",SmtRes!AB21:'SmtRes'!AB30) -> 5584.83 | CS28: =SUMIF(SmtRes!AQ21:'SmtRes'!AQ30,"=1",SmtRes!AC21:'SmtRes'!AC30) -> 1140.16 | CT28: =SUMIF(SmtRes!AQ21:'SmtRes'!AQ30,"=1",SmtRes!AD21:'SmtRes'!AD30) -> 432.81 | CU28: =AG28 -> 0 | CV28: =SUMIF(SmtRes!AQ21:'SmtRes'!AQ30,"=1",SmtRes!BU21:'SmtRes'!BU30) -> 187.6 | CW28: =SUMIF(SmtRes!AQ21:'SmtRes'!AQ30,"=1",SmtRes!BV21:'SmtRes'!BV30) -> 12.88 | CX28: =AJ28 -> 0 | CY28: =(((S28+R28)*AT28)/100) -> 10550.358 | CZ28: =(((S28+R28)*AU28)/100) -> 6672.876 | DN28: 0 | DO28: 0 | DP28: 1 | DQ28: 1 | DU28: 1003 | DV28: 100 м | DW28: 100 м | DX28: 100 | EE28: 35227794 | EF28: 2 | EG28: Общестроительные работы | EH28: 18 | EI28: Наружные сети водопровода, канализации, теплоснабжения, газопроводы | EJ28: 1 | EK28: 23001 | EL28: Наружные сети водопровода, канализации, теплоснабжения, газопроводы | EM28: ФЕР-23 | EQ28: 0 | ER28: 0 | ES28: 0 | ET28: 0 | EU28: 0 | EV28: 0 | EW28: 187.6 | EX28: 12.88 | EY28: 0 | FQ28: 0 | FR28: 0 | FS28: 0 | FX28: 117 | FY28: 74 | GD28: 1 | GF28: 1846504045 | GG28: 2 | GH28: 1 | GI28: -2 | GJ28: 0 | GK28: 0 | GL28: =ROUND(IF(AND(BH28=3,BI28=3,FS28<>0),P28,0),2) -> 0 | GM28: =ROUND(O28+X28+Y28,2)+GX28 -> 35249.83 | GN28: =IF(OR(BI28=0,BI28=1),GM28-GX28,0) -> 35249.83 | GO28: =IF(BI28=2,GM28-GX28,0) -> 0 | GP28: =IF(BI28=4,GM28-GX28,0) -> 0 | GR28: 0 | GS28: 3 | GT28: 0 | GV28: =ROUND((GT28),6) -> 0 | GW28: 1 | GX28: =ROUND(HC28*I28,2) -> 0 | HA28: 0 | HB28: 0 | HC28: =GV28*GW28 -> 0 | HN28: Пр/812-018.0-1 | HO28: Пр/774-018.0 | HP28: Наружные сети водопровода, канализации, теплоснабжения, газопроводы | HQ28: Наружные сети водопровода, канализации, теплоснабжения, газопроводы | HS28: 0 | IK28: 0
A29: 18 | B29: 1 | C29: 30 | E29: 4,1 | F29: 05.1.02.08 | G29: Трубы железобетонные безнапорные раструбные | H29: м | I29: =I28*J29 -> 9.97 | J29: 99.7 | K29: 99.7 | O29: =ROUND(CP29,2) -> 0 | P29: =ROUND(CQ29*I29,2) -> 0 | Q29: =ROUND(CR29*I29,2) -> 0 | R29: =ROUND(CS29*I29,2) -> 0 | S29: =ROUND(CT29*I29,2) -> 0 | T29: =ROUND(CU29*I29,2) -> 0 | U29: =ROUND(CV29*I29,7) -> 0 | V29: =ROUND(CW29*I29,7) -> 0 | W29: =ROUND(CX29*I29,2) -> 0 | X29: =ROUND(CY29,2) -> 0 | Y29: =ROUND(CZ29,2) -> 0 | AA29: 38182922 | AB29: =ROUND((AC29+AD29+AF29),6) -> 0 | AC29: =ROUND((ES29),6) -> 0 | AD29: =ROUND((((ET29)-(EU29))+AE29),6) -> 0 | AE29: =ROUND((EU29),6) -> 0 | AF29: =ROUND((EV29),6) -> 0 | AG29: =ROUND((AP29),6) -> 0 | AH29: =(EW29) -> 0 | AI29: =(EX29) -> 0 | AJ29: =(AS29) -> 0 | AK29: 0 | AL29: 0 | AM29: 0 | AN29: 0 | AO29: 0 | AP29: 0 | AQ29: 0 | AR29: 0 | AS29: 0 | AT29: 117 | AU29: 74 | AV29: 1 | AW29: 1 | AZ29: 1 | BA29: 1 | BB29: 1 | BC29: 1 | BH29: 3 | BI29: 1 | BM29: 23001 | BN29: 0 | BP29: 0 | BQ29: 2 | BR29: 0 | BS29: 1 | BT29: 1 | BU29: 1 | BV29: 1 | BW29: 1 | BX29: 1 | BZ29: 117 | CA29: 74 | CE29: 0 | CF29: 0 | CG29: 0 | CM29: 0 | CO29: 0 | CP29: =(P29+Q29+S29+R29) -> 0 | CQ29: =ROUND(AL29*BC29,2) -> 0 | CR29: =ROUND(AM29*BB29,2) -> 0 | CS29: =ROUND(AN29*BS29,2) -> 0 | CT29: =ROUND(AO29*BA29,2) -> 0 | CU29: =AG29 -> 0 | CV29: =AH29 -> 0 | CW29: =AI29 -> 0 | CX29: =AJ29 -> 0 | CY29: =(((S29+R29)*AT29)/100) -> 0 | CZ29: =(((S29+R29)*AU29)/100) -> 0 | DN29: 0 | DO29: 0 | DP29: 1 | DQ29: 1 | DU29: 1003 | DV29: м | DW29: м | DX29: 1 | EE29: 35227794 | EF29: 2 | EG29: Общестроительные работы | EH29: 18 | EI29: Наружные сети водопровода, канализации, теплоснабжения, газопроводы | EJ29: 1 | EK29: 23001 | EL29: Наружные сети водопровода, канализации, теплоснабжения, газопроводы | EM29: ФЕР-23 | EQ29: 0 | ER29: 0 | ES29: 0 | ET29: 0 | EU29: 0 | EV29: 0 | EW29: 0 | EX29: 0 | FQ29: 0 | FR29: 0 | FS29: 0 | FX29: 117 | FY29: 74 | GD29: 1 | GF29: 1219364707 | GG29: 2 | GH29: 1 | GI29: -2 | GJ29: 0 | GK29: 0 | GL29: =ROUND(IF(AND(BH29=3,BI29=3,FS29<>0),P29,0),2) -> 0 | GM29: =ROUND(O29+X29+Y29,2)+GX29 -> 0 | GN29: =IF(OR(BI29=0,BI29=1),GM29-GX29,0) -> 0 | GO29: =IF(BI29=2,GM29-GX29,0) -> 0 | GP29: =IF(BI29=4,GM29-GX29,0) -> 0 | GR29: 0 | GS29: 3 | GT29: 0 | GV29: =ROUND((GT29),6) -> 0 | GW29: 1 | GX29: =ROUND(HC29*I29,2) -> 0 | HA29: 0 | HB29: 0 | HC29: =GV29*GW29 -> 0 | HN29: Пр/812-018.0-1 | HO29: Пр/774-018.0 | HP29: Наружные сети водопровода, канализации, теплоснабжения, газопроводы | HQ29: Наружные сети водопровода, канализации, теплоснабжения, газопроводы | HS29: 0 | IK29: 0
A30: 17 | B30: 1 | C30: =ROW(SmtRes!A33) -> 33 | D30: =ROW(EtalonRes!A32) -> 32 | E30: 5 | F30: 01-01-087-01 | G30: Засыпка траншей и котлованов с перемещением грунта до 5 м бульдозерами мощностью: 303 кВт (410 л.с.), группа грунтов 1 | H30: 1000 м3 | I30: =ROUND(ROUND(100/1000,5),7) -> 0.1 | J30: 0 | K30: =ROUND(ROUND(100/1000,5),7) -> 0.1 | O30: =ROUND(CP30,2) -> 568.15 | P30: =SUMIF(SmtRes!AQ31:'SmtRes'!AQ33,"=1",SmtRes!DF31:'SmtRes'!DF33) -> 0 | Q30: =SUMIF(SmtRes!AQ31:'SmtRes'!AQ33,"=1",SmtRes!DG31:'SmtRes'!DG33) -> 504.49 | R30: =SUMIF(SmtRes!AQ31:'SmtRes'!AQ33,"=1",SmtRes!DH31:'SmtRes'!DH33) -> 63.66 | S30: =SUMIF(SmtRes!AQ31:'SmtRes'!AQ33,"=1",SmtRes!DI31:'SmtRes'!DI33) -> 0 | T30: =ROUND(CU30*I30,2) -> 0 | U30: =SUMIF(SmtRes!AQ31:'SmtRes'!AQ33,"=1",SmtRes!CV31:'SmtRes'!CV33) -> 0 | V30: =SUMIF(SmtRes!AQ31:'SmtRes'!AQ33,"=1",SmtRes!CW31:'SmtRes'!CW33) -> 0.09 | W30: =ROUND(CX30*I30,2) -> 0 | X30: =ROUND(CY30,2) -> 58.57 | Y30: =ROUND(CZ30,2) -> 29.28 | AA30: 38182922 | AB30: =ROUND((AC30+AD30+AF30),6) -> 5044.932 | AC30: =ROUND((0),6) -> 0 | AD30: =ROUND((((SUM(SmtRes!BR31:'SmtRes'!BR33))-(SUM(SmtRes!BS31:'SmtRes'!BS33)))+AE30),6) -> 5044.932 | AE30: =ROUND((SUM(SmtRes!BS31:'SmtRes'!BS33)),6) -> 636.615 | AF30: =ROUND((0),6) -> 0 | AG30: =ROUND((AP30),6) -> 0 | AH30: =(0) -> 0 | AI30: =(SUM(SmtRes!BV31:'SmtRes'!BV33)) -> 0.9 | AJ30: =(AS30) -> 0 | AK30: 5681.547 | AL30: 0 | AM30: 5044.932 | AN30: 636.615 | AO30: 0 | AP30: 0 | AQ30: 0 | AR30: 0.9 | AS30: 0 | AT30: 92 | AU30: 46 | AV30: 1 | AW30: 1 | AZ30: 1 | BA30: 1 | BB30: 1 | BC30: 1 | BH30: 0 | BI30: 1 | BJ30: ГЭСН-2022, 01-01-087-01, приказ Минстроя России от 18.05.2022 г. № 378/пр | BM30: 1001 | BN30: 0 | BP30: 0 | BQ30: 2 | BR30: 0 | BS30: 1 | BT30: 1 | BU30: 1 | BV30: 1 | BW30: 1 | BX30: 1 | BZ30: 92 | CA30: 46 | CE30: 0 | CF30: 0 | CG30: 0 | CM30: 0 | CO30: 0 | CP30: =(P30+Q30+S30+R30) -> 568.15 | CQ30: =SUMIF(SmtRes!AQ31:'SmtRes'!AQ33,"=1",SmtRes!AA31:'SmtRes'!AA33) -> 0 | CR30: =SUMIF(SmtRes!AQ31:'SmtRes'!AQ33,"=1",SmtRes!AB31:'SmtRes'!AB33) -> 5605.48 | CS30: =SUMIF(SmtRes!AQ31:'SmtRes'!AQ33,"=1",SmtRes!AC31:'SmtRes'!AC33) -> 707.35 | CT30: =SUMIF(SmtRes!AQ31:'SmtRes'!AQ33,"=1",SmtRes!AD31:'SmtRes'!AD33) -> 0 | CU30: =AG30 -> 0 | CV30: =SUMIF(SmtRes!AQ31:'SmtRes'!AQ33,"=1",SmtRes!BU31:'SmtRes'!BU33) -> 0 | CW30: =SUMIF(SmtRes!AQ31:'SmtRes'!AQ33,"=1",SmtRes!BV31:'SmtRes'!BV33) -> 0.9 | CX30: =AJ30 -> 0 | CY30: =(((S30+R30)*AT30)/100) -> 58.5672 | CZ30: =(((S30+R30)*AU30)/100) -> 29.2836 | DN30: 0 | DO30: 0 | DP30: 1 | DQ30: 1 | DU30: 1007 | DV30: 1000 м3 | DW30: 1000 м3 | DX30: 1000 | EE30: 35227734 | EF30: 2 | EG30: Общестроительные работы | EH30: 1 | EI30: Земляные работы | EJ30: 1 | EK30: 1001 | EL30: Земляные работы, выполняемые: механизированным способом | EM30: ФЕР-01 | EQ30: 0 | ER30: 0 | ES30: 0 | ET30: 0 | EU30: 0 | EV30: 0 | EW30: 0 | EX30: 0.9 | EY30: 0 | FQ30: 0 | FR30: 0 | FS30: 0 | FX30: 92 | FY30: 46 | GD30: 1 | GF30: -986908504 | GG30: 2 | GH30: 1 | GI30: -2 | GJ30: 0 | GK30: 0 | GL30: =ROUND(IF(AND(BH30=3,BI30=3,FS30<>0),P30,0),2) -> 0 | GM30: =ROUND(O30+X30+Y30,2)+GX30 -> 656 | GN30: =IF(OR(BI30=0,BI30=1),GM30-GX30,0) -> 656 | GO30: =IF(BI30=2,GM30-GX30,0) -> 0 | GP30: =IF(BI30=4,GM30-GX30,0) -> 0 | GR30: 0 | GS30: 3 | GT30: 0 | GV30: =ROUND((GT30),6) -> 0 | GW30: 1 | GX30: =ROUND(HC30*I30,2) -> 0 | HA30: 0 | HB30: 0 | HC30: =GV30*GW30 -> 0 | HN30: Пр/812-001.1-1 | HO30: Пр/774-001.1 | HP30: Земляные работы, выполняемые: механизированным способом | HQ30: Земляные работы, выполняемые: механизированным способом | HS30: 0 | IK30: 0
